Traceback (most recent call last):
  File "/home/biommcwj/virtualenv/rrb_mnc/3.6/lib/python3.6/site-packages/django/db/backends/mysql/base.py", line 15, in <module>
    import MySQLdb as Database
ModuleNotFoundError: No module named 'MySQLdb'

The above exception was the direct cause of the following exception:

Traceback (most recent call last):
  File "/home/biommcwj/rrb_mnc/passenger_wsgi.py", line 1, in <module>
    from images.wsgi import  application
  File "/home/biommcwj/rrb_mnc/images/wsgi.py", line 16, in <module>
    application = get_wsgi_application()
  File "/home/biommcwj/virtualenv/rrb_mnc/3.6/lib/python3.6/site-packages/django/core/wsgi.py", line 12, in get_wsgi_application
    django.setup(set_prefix=False)
  File "/home/biommcwj/virtualenv/rrb_mnc/3.6/lib/python3.6/site-packages/django/__init__.py", line 24, in setup
    apps.populate(settings.INSTALLED_APPS)
  File "/home/biommcwj/virtualenv/rrb_mnc/3.6/lib/python3.6/site-packages/django/apps/registry.py", line 114, in populate
    app_config.import_models()
  File "/home/biommcwj/virtualenv/rrb_mnc/3.6/lib/python3.6/site-packages/django/apps/config.py", line 301, in import_models
    self.models_module = import_module(models_module_name)
  File "/opt/alt/python36/lib64/python3.6/importlib/__init__.py", line 126, in import_module
    return _bootstrap._gcd_import(name[level:], package, level)
  File "/home/biommcwj/virtualenv/rrb_mnc/3.6/lib/python3.6/site-packages/django/contrib/auth/models.py", line 3, in <module>
    from django.contrib.auth.base_user import AbstractBaseUser, BaseUserManager
  File "/home/biommcwj/virtualenv/rrb_mnc/3.6/lib/python3.6/site-packages/django/contrib/auth/base_user.py", line 48, in <module>
    class AbstractBaseUser(models.Model):
  File "/home/biommcwj/virtualenv/rrb_mnc/3.6/lib/python3.6/site-packages/django/db/models/base.py", line 122, in __new__
    new_class.add_to_class('_meta', Options(meta, app_label))
  File "/home/biommcwj/virtualenv/rrb_mnc/3.6/lib/python3.6/site-packages/django/db/models/base.py", line 326, in add_to_class
    value.contribute_to_class(cls, name)
  File "/home/biommcwj/virtualenv/rrb_mnc/3.6/lib/python3.6/site-packages/django/db/models/options.py", line 207, in contribute_to_class
    self.db_table = truncate_name(self.db_table, connection.ops.max_name_length())
  File "/home/biommcwj/virtualenv/rrb_mnc/3.6/lib/python3.6/site-packages/django/utils/connection.py", line 15, in __getattr__
    return getattr(self._connections[self._alias], item)
  File "/home/biommcwj/virtualenv/rrb_mnc/3.6/lib/python3.6/site-packages/django/utils/connection.py", line 62, in __getitem__
    conn = self.create_connection(alias)
  File "/home/biommcwj/virtualenv/rrb_mnc/3.6/lib/python3.6/site-packages/django/db/utils.py", line 204, in create_connection
    backend = load_backend(db['ENGINE'])
  File "/home/biommcwj/virtualenv/rrb_mnc/3.6/lib/python3.6/site-packages/django/db/utils.py", line 111, in load_backend
    return import_module('%s.base' % backend_name)
  File "/opt/alt/python36/lib64/python3.6/importlib/__init__.py", line 126, in import_module
    return _bootstrap._gcd_import(name[level:], package, level)
  File "/home/biommcwj/virtualenv/rrb_mnc/3.6/lib/python3.6/site-packages/django/db/backends/mysql/base.py", line 20, in <module>
    ) from err
django.core.exceptions.ImproperlyConfigured: Error loading MySQLdb module.
Did you install mysqlclient?
Traceback (most recent call last):
  File "/home/biommcwj/rrb_mnc/passenger_wsgi.py", line 1, in <module>
    from images.wsgi import  application
  File "/home/biommcwj/rrb_mnc/images/wsgi.py", line 16, in <module>
    application = get_wsgi_application()
  File "/home/biommcwj/virtualenv/rrb_mnc/3.6/lib/python3.6/site-packages/django/core/wsgi.py", line 12, in get_wsgi_application
    django.setup(set_prefix=False)
  File "/home/biommcwj/virtualenv/rrb_mnc/3.6/lib/python3.6/site-packages/django/__init__.py", line 24, in setup
    apps.populate(settings.INSTALLED_APPS)
  File "/home/biommcwj/virtualenv/rrb_mnc/3.6/lib/python3.6/site-packages/django/apps/registry.py", line 83, in populate
    raise RuntimeError("populate() isn't reentrant")
RuntimeError: populate() isn't reentrant
Traceback (most recent call last):
  File "/home/biommcwj/virtualenv/rrb_mnc/3.6/lib/python3.6/site-packages/django/db/backends/mysql/base.py", line 15, in <module>
    import MySQLdb as Database
ModuleNotFoundError: No module named 'MySQLdb'

The above exception was the direct cause of the following exception:

Traceback (most recent call last):
  File "/home/biommcwj/rrb_mnc/passenger_wsgi.py", line 1, in <module>
    from images.wsgi import  application
  File "/home/biommcwj/rrb_mnc/images/wsgi.py", line 16, in <module>
    application = get_wsgi_application()
  File "/home/biommcwj/virtualenv/rrb_mnc/3.6/lib/python3.6/site-packages/django/core/wsgi.py", line 12, in get_wsgi_application
    django.setup(set_prefix=False)
  File "/home/biommcwj/virtualenv/rrb_mnc/3.6/lib/python3.6/site-packages/django/__init__.py", line 24, in setup
    apps.populate(settings.INSTALLED_APPS)
  File "/home/biommcwj/virtualenv/rrb_mnc/3.6/lib/python3.6/site-packages/django/apps/registry.py", line 114, in populate
    app_config.import_models()
  File "/home/biommcwj/virtualenv/rrb_mnc/3.6/lib/python3.6/site-packages/django/apps/config.py", line 301, in import_models
    self.models_module = import_module(models_module_name)
  File "/opt/alt/python36/lib64/python3.6/importlib/__init__.py", line 126, in import_module
    return _bootstrap._gcd_import(name[level:], package, level)
  File "/home/biommcwj/virtualenv/rrb_mnc/3.6/lib/python3.6/site-packages/django/contrib/auth/models.py", line 3, in <module>
    from django.contrib.auth.base_user import AbstractBaseUser, BaseUserManager
  File "/home/biommcwj/virtualenv/rrb_mnc/3.6/lib/python3.6/site-packages/django/contrib/auth/base_user.py", line 48, in <module>
    class AbstractBaseUser(models.Model):
  File "/home/biommcwj/virtualenv/rrb_mnc/3.6/lib/python3.6/site-packages/django/db/models/base.py", line 122, in __new__
    new_class.add_to_class('_meta', Options(meta, app_label))
  File "/home/biommcwj/virtualenv/rrb_mnc/3.6/lib/python3.6/site-packages/django/db/models/base.py", line 326, in add_to_class
    value.contribute_to_class(cls, name)
  File "/home/biommcwj/virtualenv/rrb_mnc/3.6/lib/python3.6/site-packages/django/db/models/options.py", line 207, in contribute_to_class
    self.db_table = truncate_name(self.db_table, connection.ops.max_name_length())
  File "/home/biommcwj/virtualenv/rrb_mnc/3.6/lib/python3.6/site-packages/django/utils/connection.py", line 15, in __getattr__
    return getattr(self._connections[self._alias], item)
  File "/home/biommcwj/virtualenv/rrb_mnc/3.6/lib/python3.6/site-packages/django/utils/connection.py", line 62, in __getitem__
    conn = self.create_connection(alias)
  File "/home/biommcwj/virtualenv/rrb_mnc/3.6/lib/python3.6/site-packages/django/db/utils.py", line 204, in create_connection
    backend = load_backend(db['ENGINE'])
  File "/home/biommcwj/virtualenv/rrb_mnc/3.6/lib/python3.6/site-packages/django/db/utils.py", line 111, in load_backend
    return import_module('%s.base' % backend_name)
  File "/opt/alt/python36/lib64/python3.6/importlib/__init__.py", line 126, in import_module
    return _bootstrap._gcd_import(name[level:], package, level)
  File "/home/biommcwj/virtualenv/rrb_mnc/3.6/lib/python3.6/site-packages/django/db/backends/mysql/base.py", line 20, in <module>
    ) from err
django.core.exceptions.ImproperlyConfigured: Error loading MySQLdb module.
Did you install mysqlclient?
Traceback (most recent call last):
  File "/home/biommcwj/virtualenv/rrb_mnc/3.6/lib/python3.6/site-packages/django/db/backends/mysql/base.py", line 15, in <module>
    import MySQLdb as Database
ModuleNotFoundError: No module named 'MySQLdb'

The above exception was the direct cause of the following exception:

Traceback (most recent call last):
  File "/home/biommcwj/rrb_mnc/passenger_wsgi.py", line 1, in <module>
    from images.wsgi import  application
  File "/home/biommcwj/rrb_mnc/images/wsgi.py", line 16, in <module>
    application = get_wsgi_application()
  File "/home/biommcwj/virtualenv/rrb_mnc/3.6/lib/python3.6/site-packages/django/core/wsgi.py", line 12, in get_wsgi_application
    django.setup(set_prefix=False)
  File "/home/biommcwj/virtualenv/rrb_mnc/3.6/lib/python3.6/site-packages/django/__init__.py", line 24, in setup
    apps.populate(settings.INSTALLED_APPS)
  File "/home/biommcwj/virtualenv/rrb_mnc/3.6/lib/python3.6/site-packages/django/apps/registry.py", line 114, in populate
    app_config.import_models()
  File "/home/biommcwj/virtualenv/rrb_mnc/3.6/lib/python3.6/site-packages/django/apps/config.py", line 301, in import_models
    self.models_module = import_module(models_module_name)
  File "/opt/alt/python36/lib64/python3.6/importlib/__init__.py", line 126, in import_module
    return _bootstrap._gcd_import(name[level:], package, level)
  File "/home/biommcwj/virtualenv/rrb_mnc/3.6/lib/python3.6/site-packages/django/contrib/auth/models.py", line 3, in <module>
    from django.contrib.auth.base_user import AbstractBaseUser, BaseUserManager
  File "/home/biommcwj/virtualenv/rrb_mnc/3.6/lib/python3.6/site-packages/django/contrib/auth/base_user.py", line 48, in <module>
    class AbstractBaseUser(models.Model):
  File "/home/biommcwj/virtualenv/rrb_mnc/3.6/lib/python3.6/site-packages/django/db/models/base.py", line 122, in __new__
    new_class.add_to_class('_meta', Options(meta, app_label))
  File "/home/biommcwj/virtualenv/rrb_mnc/3.6/lib/python3.6/site-packages/django/db/models/base.py", line 326, in add_to_class
    value.contribute_to_class(cls, name)
  File "/home/biommcwj/virtualenv/rrb_mnc/3.6/lib/python3.6/site-packages/django/db/models/options.py", line 207, in contribute_to_class
    self.db_table = truncate_name(self.db_table, connection.ops.max_name_length())
  File "/home/biommcwj/virtualenv/rrb_mnc/3.6/lib/python3.6/site-packages/django/utils/connection.py", line 15, in __getattr__
    return getattr(self._connections[self._alias], item)
  File "/home/biommcwj/virtualenv/rrb_mnc/3.6/lib/python3.6/site-packages/django/utils/connection.py", line 62, in __getitem__
    conn = self.create_connection(alias)
  File "/home/biommcwj/virtualenv/rrb_mnc/3.6/lib/python3.6/site-packages/django/db/utils.py", line 204, in create_connection
    backend = load_backend(db['ENGINE'])
  File "/home/biommcwj/virtualenv/rrb_mnc/3.6/lib/python3.6/site-packages/django/db/utils.py", line 111, in load_backend
    return import_module('%s.base' % backend_name)
  File "/opt/alt/python36/lib64/python3.6/importlib/__init__.py", line 126, in import_module
    return _bootstrap._gcd_import(name[level:], package, level)
  File "/home/biommcwj/virtualenv/rrb_mnc/3.6/lib/python3.6/site-packages/django/db/backends/mysql/base.py", line 20, in <module>
    ) from err
django.core.exceptions.ImproperlyConfigured: Error loading MySQLdb module.
Did you install mysqlclient?
Traceback (most recent call last):
  File "/home/biommcwj/rrb_mnc/passenger_wsgi.py", line 1, in <module>
    from images.wsgi import  application
  File "/home/biommcwj/rrb_mnc/images/wsgi.py", line 16, in <module>
    application = get_wsgi_application()
  File "/home/biommcwj/virtualenv/rrb_mnc/3.6/lib/python3.6/site-packages/django/core/wsgi.py", line 12, in get_wsgi_application
    django.setup(set_prefix=False)
  File "/home/biommcwj/virtualenv/rrb_mnc/3.6/lib/python3.6/site-packages/django/__init__.py", line 24, in setup
    apps.populate(settings.INSTALLED_APPS)
  File "/home/biommcwj/virtualenv/rrb_mnc/3.6/lib/python3.6/site-packages/django/apps/registry.py", line 83, in populate
    raise RuntimeError("populate() isn't reentrant")
RuntimeError: populate() isn't reentrant
Traceback (most recent call last):
  File "/home/biommcwj/virtualenv/rrb_mnc/3.6/lib/python3.6/site-packages/django/db/backends/mysql/base.py", line 15, in <module>
    import MySQLdb as Database
ModuleNotFoundError: No module named 'MySQLdb'

The above exception was the direct cause of the following exception:

Traceback (most recent call last):
  File "/home/biommcwj/rrb_mnc/passenger_wsgi.py", line 1, in <module>
    from images.wsgi import  application
  File "/home/biommcwj/rrb_mnc/images/wsgi.py", line 16, in <module>
    application = get_wsgi_application()
  File "/home/biommcwj/virtualenv/rrb_mnc/3.6/lib/python3.6/site-packages/django/core/wsgi.py", line 12, in get_wsgi_application
    django.setup(set_prefix=False)
  File "/home/biommcwj/virtualenv/rrb_mnc/3.6/lib/python3.6/site-packages/django/__init__.py", line 24, in setup
    apps.populate(settings.INSTALLED_APPS)
  File "/home/biommcwj/virtualenv/rrb_mnc/3.6/lib/python3.6/site-packages/django/apps/registry.py", line 114, in populate
    app_config.import_models()
  File "/home/biommcwj/virtualenv/rrb_mnc/3.6/lib/python3.6/site-packages/django/apps/config.py", line 301, in import_models
    self.models_module = import_module(models_module_name)
  File "/opt/alt/python36/lib64/python3.6/importlib/__init__.py", line 126, in import_module
    return _bootstrap._gcd_import(name[level:], package, level)
  File "/home/biommcwj/virtualenv/rrb_mnc/3.6/lib/python3.6/site-packages/django/contrib/auth/models.py", line 3, in <module>
    from django.contrib.auth.base_user import AbstractBaseUser, BaseUserManager
  File "/home/biommcwj/virtualenv/rrb_mnc/3.6/lib/python3.6/site-packages/django/contrib/auth/base_user.py", line 48, in <module>
    class AbstractBaseUser(models.Model):
  File "/home/biommcwj/virtualenv/rrb_mnc/3.6/lib/python3.6/site-packages/django/db/models/base.py", line 122, in __new__
    new_class.add_to_class('_meta', Options(meta, app_label))
  File "/home/biommcwj/virtualenv/rrb_mnc/3.6/lib/python3.6/site-packages/django/db/models/base.py", line 326, in add_to_class
    value.contribute_to_class(cls, name)
  File "/home/biommcwj/virtualenv/rrb_mnc/3.6/lib/python3.6/site-packages/django/db/models/options.py", line 207, in contribute_to_class
    self.db_table = truncate_name(self.db_table, connection.ops.max_name_length())
  File "/home/biommcwj/virtualenv/rrb_mnc/3.6/lib/python3.6/site-packages/django/utils/connection.py", line 15, in __getattr__
    return getattr(self._connections[self._alias], item)
  File "/home/biommcwj/virtualenv/rrb_mnc/3.6/lib/python3.6/site-packages/django/utils/connection.py", line 62, in __getitem__
    conn = self.create_connection(alias)
  File "/home/biommcwj/virtualenv/rrb_mnc/3.6/lib/python3.6/site-packages/django/db/utils.py", line 204, in create_connection
    backend = load_backend(db['ENGINE'])
  File "/home/biommcwj/virtualenv/rrb_mnc/3.6/lib/python3.6/site-packages/django/db/utils.py", line 111, in load_backend
    return import_module('%s.base' % backend_name)
  File "/opt/alt/python36/lib64/python3.6/importlib/__init__.py", line 126, in import_module
    return _bootstrap._gcd_import(name[level:], package, level)
  File "/home/biommcwj/virtualenv/rrb_mnc/3.6/lib/python3.6/site-packages/django/db/backends/mysql/base.py", line 20, in <module>
    ) from err
django.core.exceptions.ImproperlyConfigured: Error loading MySQLdb module.
Did you install mysqlclient?
Traceback (most recent call last):
  File "/home/biommcwj/rrb_mnc/passenger_wsgi.py", line 1, in <module>
    from images.wsgi import  application
  File "/home/biommcwj/rrb_mnc/images/wsgi.py", line 16, in <module>
    application = get_wsgi_application()
  File "/home/biommcwj/virtualenv/rrb_mnc/3.6/lib/python3.6/site-packages/django/core/wsgi.py", line 12, in get_wsgi_application
    django.setup(set_prefix=False)
  File "/home/biommcwj/virtualenv/rrb_mnc/3.6/lib/python3.6/site-packages/django/__init__.py", line 24, in setup
    apps.populate(settings.INSTALLED_APPS)
  File "/home/biommcwj/virtualenv/rrb_mnc/3.6/lib/python3.6/site-packages/django/apps/registry.py", line 83, in populate
    raise RuntimeError("populate() isn't reentrant")
RuntimeError: populate() isn't reentrant
Traceback (most recent call last):
  File "/home/biommcwj/rrb_mnc/passenger_wsgi.py", line 1, in <module>
    from images.wsgi import  application
  File "/home/biommcwj/rrb_mnc/images/wsgi.py", line 16, in <module>
    application = get_wsgi_application()
  File "/home/biommcwj/virtualenv/rrb_mnc/3.6/lib/python3.6/site-packages/django/core/wsgi.py", line 12, in get_wsgi_application
    django.setup(set_prefix=False)
  File "/home/biommcwj/virtualenv/rrb_mnc/3.6/lib/python3.6/site-packages/django/__init__.py", line 24, in setup
    apps.populate(settings.INSTALLED_APPS)
  File "/home/biommcwj/virtualenv/rrb_mnc/3.6/lib/python3.6/site-packages/django/apps/registry.py", line 83, in populate
    raise RuntimeError("populate() isn't reentrant")
RuntimeError: populate() isn't reentrant
Traceback (most recent call last):
  File "/home/biommcwj/rrb_mnc/passenger_wsgi.py", line 1, in <module>
    from images.wsgi import  application
  File "/home/biommcwj/rrb_mnc/images/wsgi.py", line 16, in <module>
    application = get_wsgi_application()
  File "/home/biommcwj/virtualenv/rrb_mnc/3.6/lib/python3.6/site-packages/django/core/wsgi.py", line 12, in get_wsgi_application
    django.setup(set_prefix=False)
  File "/home/biommcwj/virtualenv/rrb_mnc/3.6/lib/python3.6/site-packages/django/__init__.py", line 24, in setup
    apps.populate(settings.INSTALLED_APPS)
  File "/home/biommcwj/virtualenv/rrb_mnc/3.6/lib/python3.6/site-packages/django/apps/registry.py", line 83, in populate
    raise RuntimeError("populate() isn't reentrant")
RuntimeError: populate() isn't reentrant
Traceback (most recent call last):
  File "/home/biommcwj/rrb_mnc/passenger_wsgi.py", line 1, in <module>
    from images.wsgi import  application
  File "/home/biommcwj/rrb_mnc/images/wsgi.py", line 16, in <module>
    application = get_wsgi_application()
  File "/home/biommcwj/virtualenv/rrb_mnc/3.6/lib/python3.6/site-packages/django/core/wsgi.py", line 12, in get_wsgi_application
    django.setup(set_prefix=False)
  File "/home/biommcwj/virtualenv/rrb_mnc/3.6/lib/python3.6/site-packages/django/__init__.py", line 24, in setup
    apps.populate(settings.INSTALLED_APPS)
  File "/home/biommcwj/virtualenv/rrb_mnc/3.6/lib/python3.6/site-packages/django/apps/registry.py", line 83, in populate
    raise RuntimeError("populate() isn't reentrant")
RuntimeError: populate() isn't reentrant
Traceback (most recent call last):
  File "/home/biommcwj/virtualenv/rrb_mnc/3.6/lib/python3.6/site-packages/django/db/backends/mysql/base.py", line 15, in <module>
    import MySQLdb as Database
ModuleNotFoundError: No module named 'MySQLdb'

The above exception was the direct cause of the following exception:

Traceback (most recent call last):
  File "/home/biommcwj/rrb_mnc/passenger_wsgi.py", line 1, in <module>
    from images.wsgi import  application
  File "/home/biommcwj/rrb_mnc/images/wsgi.py", line 16, in <module>
    application = get_wsgi_application()
  File "/home/biommcwj/virtualenv/rrb_mnc/3.6/lib/python3.6/site-packages/django/core/wsgi.py", line 12, in get_wsgi_application
    django.setup(set_prefix=False)
  File "/home/biommcwj/virtualenv/rrb_mnc/3.6/lib/python3.6/site-packages/django/__init__.py", line 24, in setup
    apps.populate(settings.INSTALLED_APPS)
  File "/home/biommcwj/virtualenv/rrb_mnc/3.6/lib/python3.6/site-packages/django/apps/registry.py", line 114, in populate
    app_config.import_models()
  File "/home/biommcwj/virtualenv/rrb_mnc/3.6/lib/python3.6/site-packages/django/apps/config.py", line 301, in import_models
    self.models_module = import_module(models_module_name)
  File "/opt/alt/python36/lib64/python3.6/importlib/__init__.py", line 126, in import_module
    return _bootstrap._gcd_import(name[level:], package, level)
  File "/home/biommcwj/virtualenv/rrb_mnc/3.6/lib/python3.6/site-packages/django/contrib/auth/models.py", line 3, in <module>
    from django.contrib.auth.base_user import AbstractBaseUser, BaseUserManager
  File "/home/biommcwj/virtualenv/rrb_mnc/3.6/lib/python3.6/site-packages/django/contrib/auth/base_user.py", line 48, in <module>
    class AbstractBaseUser(models.Model):
  File "/home/biommcwj/virtualenv/rrb_mnc/3.6/lib/python3.6/site-packages/django/db/models/base.py", line 122, in __new__
    new_class.add_to_class('_meta', Options(meta, app_label))
  File "/home/biommcwj/virtualenv/rrb_mnc/3.6/lib/python3.6/site-packages/django/db/models/base.py", line 326, in add_to_class
    value.contribute_to_class(cls, name)
  File "/home/biommcwj/virtualenv/rrb_mnc/3.6/lib/python3.6/site-packages/django/db/models/options.py", line 207, in contribute_to_class
    self.db_table = truncate_name(self.db_table, connection.ops.max_name_length())
  File "/home/biommcwj/virtualenv/rrb_mnc/3.6/lib/python3.6/site-packages/django/utils/connection.py", line 15, in __getattr__
    return getattr(self._connections[self._alias], item)
  File "/home/biommcwj/virtualenv/rrb_mnc/3.6/lib/python3.6/site-packages/django/utils/connection.py", line 62, in __getitem__
    conn = self.create_connection(alias)
  File "/home/biommcwj/virtualenv/rrb_mnc/3.6/lib/python3.6/site-packages/django/db/utils.py", line 204, in create_connection
    backend = load_backend(db['ENGINE'])
  File "/home/biommcwj/virtualenv/rrb_mnc/3.6/lib/python3.6/site-packages/django/db/utils.py", line 111, in load_backend
    return import_module('%s.base' % backend_name)
  File "/opt/alt/python36/lib64/python3.6/importlib/__init__.py", line 126, in import_module
    return _bootstrap._gcd_import(name[level:], package, level)
  File "/home/biommcwj/virtualenv/rrb_mnc/3.6/lib/python3.6/site-packages/django/db/backends/mysql/base.py", line 20, in <module>
    ) from err
django.core.exceptions.ImproperlyConfigured: Error loading MySQLdb module.
Did you install mysqlclient?
Traceback (most recent call last):
  File "/home/biommcwj/virtualenv/rrb_mnc/3.6/lib/python3.6/site-packages/django/db/backends/mysql/base.py", line 15, in <module>
    import MySQLdb as Database
ModuleNotFoundError: No module named 'MySQLdb'

The above exception was the direct cause of the following exception:

Traceback (most recent call last):
  File "/home/biommcwj/rrb_mnc/passenger_wsgi.py", line 1, in <module>
    from images.wsgi import  application
  File "/home/biommcwj/rrb_mnc/images/wsgi.py", line 16, in <module>
    application = get_wsgi_application()
  File "/home/biommcwj/virtualenv/rrb_mnc/3.6/lib/python3.6/site-packages/django/core/wsgi.py", line 12, in get_wsgi_application
    django.setup(set_prefix=False)
  File "/home/biommcwj/virtualenv/rrb_mnc/3.6/lib/python3.6/site-packages/django/__init__.py", line 24, in setup
    apps.populate(settings.INSTALLED_APPS)
  File "/home/biommcwj/virtualenv/rrb_mnc/3.6/lib/python3.6/site-packages/django/apps/registry.py", line 114, in populate
    app_config.import_models()
  File "/home/biommcwj/virtualenv/rrb_mnc/3.6/lib/python3.6/site-packages/django/apps/config.py", line 301, in import_models
    self.models_module = import_module(models_module_name)
  File "/opt/alt/python36/lib64/python3.6/importlib/__init__.py", line 126, in import_module
    return _bootstrap._gcd_import(name[level:], package, level)
  File "/home/biommcwj/virtualenv/rrb_mnc/3.6/lib/python3.6/site-packages/django/contrib/auth/models.py", line 3, in <module>
    from django.contrib.auth.base_user import AbstractBaseUser, BaseUserManager
  File "/home/biommcwj/virtualenv/rrb_mnc/3.6/lib/python3.6/site-packages/django/contrib/auth/base_user.py", line 48, in <module>
    class AbstractBaseUser(models.Model):
  File "/home/biommcwj/virtualenv/rrb_mnc/3.6/lib/python3.6/site-packages/django/db/models/base.py", line 122, in __new__
    new_class.add_to_class('_meta', Options(meta, app_label))
  File "/home/biommcwj/virtualenv/rrb_mnc/3.6/lib/python3.6/site-packages/django/db/models/base.py", line 326, in add_to_class
    value.contribute_to_class(cls, name)
  File "/home/biommcwj/virtualenv/rrb_mnc/3.6/lib/python3.6/site-packages/django/db/models/options.py", line 207, in contribute_to_class
    self.db_table = truncate_name(self.db_table, connection.ops.max_name_length())
  File "/home/biommcwj/virtualenv/rrb_mnc/3.6/lib/python3.6/site-packages/django/utils/connection.py", line 15, in __getattr__
    return getattr(self._connections[self._alias], item)
  File "/home/biommcwj/virtualenv/rrb_mnc/3.6/lib/python3.6/site-packages/django/utils/connection.py", line 62, in __getitem__
    conn = self.create_connection(alias)
  File "/home/biommcwj/virtualenv/rrb_mnc/3.6/lib/python3.6/site-packages/django/db/utils.py", line 204, in create_connection
    backend = load_backend(db['ENGINE'])
  File "/home/biommcwj/virtualenv/rrb_mnc/3.6/lib/python3.6/site-packages/django/db/utils.py", line 111, in load_backend
    return import_module('%s.base' % backend_name)
  File "/opt/alt/python36/lib64/python3.6/importlib/__init__.py", line 126, in import_module
    return _bootstrap._gcd_import(name[level:], package, level)
  File "/home/biommcwj/virtualenv/rrb_mnc/3.6/lib/python3.6/site-packages/django/db/backends/mysql/base.py", line 20, in <module>
    ) from err
django.core.exceptions.ImproperlyConfigured: Error loading MySQLdb module.
Did you install mysqlclient?
Traceback (most recent call last):
  File "/home/biommcwj/rrb_mnc/passenger_wsgi.py", line 1, in <module>
    from images.wsgi import  application
  File "/home/biommcwj/rrb_mnc/images/wsgi.py", line 16, in <module>
    application = get_wsgi_application()
  File "/home/biommcwj/virtualenv/rrb_mnc/3.6/lib/python3.6/site-packages/django/core/wsgi.py", line 12, in get_wsgi_application
    django.setup(set_prefix=False)
  File "/home/biommcwj/virtualenv/rrb_mnc/3.6/lib/python3.6/site-packages/django/__init__.py", line 24, in setup
    apps.populate(settings.INSTALLED_APPS)
  File "/home/biommcwj/virtualenv/rrb_mnc/3.6/lib/python3.6/site-packages/django/apps/registry.py", line 83, in populate
    raise RuntimeError("populate() isn't reentrant")
RuntimeError: populate() isn't reentrant
Traceback (most recent call last):
  File "/home/biommcwj/rrb_mnc/passenger_wsgi.py", line 1, in <module>
    from images.wsgi import  application
  File "/home/biommcwj/rrb_mnc/images/wsgi.py", line 16, in <module>
    application = get_wsgi_application()
  File "/home/biommcwj/virtualenv/rrb_mnc/3.6/lib/python3.6/site-packages/django/core/wsgi.py", line 12, in get_wsgi_application
    django.setup(set_prefix=False)
  File "/home/biommcwj/virtualenv/rrb_mnc/3.6/lib/python3.6/site-packages/django/__init__.py", line 24, in setup
    apps.populate(settings.INSTALLED_APPS)
  File "/home/biommcwj/virtualenv/rrb_mnc/3.6/lib/python3.6/site-packages/django/apps/registry.py", line 114, in populate
    app_config.import_models()
  File "/home/biommcwj/virtualenv/rrb_mnc/3.6/lib/python3.6/site-packages/django/apps/config.py", line 301, in import_models
    self.models_module = import_module(models_module_name)
  File "/opt/alt/python36/lib64/python3.6/importlib/__init__.py", line 126, in import_module
    return _bootstrap._gcd_import(name[level:], package, level)
  File "/home/biommcwj/virtualenv/rrb_mnc/3.6/lib/python3.6/site-packages/django/contrib/auth/models.py", line 3, in <module>
    from django.contrib.auth.base_user import AbstractBaseUser, BaseUserManager
  File "/home/biommcwj/virtualenv/rrb_mnc/3.6/lib/python3.6/site-packages/django/contrib/auth/base_user.py", line 48, in <module>
    class AbstractBaseUser(models.Model):
  File "/home/biommcwj/virtualenv/rrb_mnc/3.6/lib/python3.6/site-packages/django/db/models/base.py", line 122, in __new__
    new_class.add_to_class('_meta', Options(meta, app_label))
  File "/home/biommcwj/virtualenv/rrb_mnc/3.6/lib/python3.6/site-packages/django/db/models/base.py", line 326, in add_to_class
    value.contribute_to_class(cls, name)
  File "/home/biommcwj/virtualenv/rrb_mnc/3.6/lib/python3.6/site-packages/django/db/models/options.py", line 207, in contribute_to_class
    self.db_table = truncate_name(self.db_table, connection.ops.max_name_length())
  File "/home/biommcwj/virtualenv/rrb_mnc/3.6/lib/python3.6/site-packages/django/utils/connection.py", line 15, in __getattr__
    return getattr(self._connections[self._alias], item)
  File "/home/biommcwj/virtualenv/rrb_mnc/3.6/lib/python3.6/site-packages/django/utils/connection.py", line 62, in __getitem__
    conn = self.create_connection(alias)
  File "/home/biommcwj/virtualenv/rrb_mnc/3.6/lib/python3.6/site-packages/django/db/utils.py", line 204, in create_connection
    backend = load_backend(db['ENGINE'])
  File "/home/biommcwj/virtualenv/rrb_mnc/3.6/lib/python3.6/site-packages/django/db/utils.py", line 111, in load_backend
    return import_module('%s.base' % backend_name)
  File "/opt/alt/python36/lib64/python3.6/importlib/__init__.py", line 126, in import_module
    return _bootstrap._gcd_import(name[level:], package, level)
  File "/home/biommcwj/virtualenv/rrb_mnc/3.6/lib/python3.6/site-packages/django/db/backends/sqlite3/base.py", line 73, in <module>
    check_sqlite_version()
  File "/home/biommcwj/virtualenv/rrb_mnc/3.6/lib/python3.6/site-packages/django/db/backends/sqlite3/base.py", line 69, in check_sqlite_version
    'SQLite 3.9.0 or later is required (found %s).' % Database.sqlite_version
django.core.exceptions.ImproperlyConfigured: SQLite 3.9.0 or later is required (found 3.7.0.1).
Traceback (most recent call last):
  File "/home/biommcwj/rrb_mnc/passenger_wsgi.py", line 1, in <module>
    from images.wsgi import  application
  File "/home/biommcwj/rrb_mnc/images/wsgi.py", line 16, in <module>
    application = get_wsgi_application()
  File "/home/biommcwj/virtualenv/rrb_mnc/3.6/lib/python3.6/site-packages/django/core/wsgi.py", line 12, in get_wsgi_application
    django.setup(set_prefix=False)
  File "/home/biommcwj/virtualenv/rrb_mnc/3.6/lib/python3.6/site-packages/django/__init__.py", line 24, in setup
    apps.populate(settings.INSTALLED_APPS)
  File "/home/biommcwj/virtualenv/rrb_mnc/3.6/lib/python3.6/site-packages/django/apps/registry.py", line 114, in populate
    app_config.import_models()
  File "/home/biommcwj/virtualenv/rrb_mnc/3.6/lib/python3.6/site-packages/django/apps/config.py", line 301, in import_models
    self.models_module = import_module(models_module_name)
  File "/opt/alt/python36/lib64/python3.6/importlib/__init__.py", line 126, in import_module
    return _bootstrap._gcd_import(name[level:], package, level)
  File "/home/biommcwj/virtualenv/rrb_mnc/3.6/lib/python3.6/site-packages/django/contrib/auth/models.py", line 3, in <module>
    from django.contrib.auth.base_user import AbstractBaseUser, BaseUserManager
  File "/home/biommcwj/virtualenv/rrb_mnc/3.6/lib/python3.6/site-packages/django/contrib/auth/base_user.py", line 48, in <module>
    class AbstractBaseUser(models.Model):
  File "/home/biommcwj/virtualenv/rrb_mnc/3.6/lib/python3.6/site-packages/django/db/models/base.py", line 122, in __new__
    new_class.add_to_class('_meta', Options(meta, app_label))
  File "/home/biommcwj/virtualenv/rrb_mnc/3.6/lib/python3.6/site-packages/django/db/models/base.py", line 326, in add_to_class
    value.contribute_to_class(cls, name)
  File "/home/biommcwj/virtualenv/rrb_mnc/3.6/lib/python3.6/site-packages/django/db/models/options.py", line 207, in contribute_to_class
    self.db_table = truncate_name(self.db_table, connection.ops.max_name_length())
  File "/home/biommcwj/virtualenv/rrb_mnc/3.6/lib/python3.6/site-packages/django/utils/connection.py", line 15, in __getattr__
    return getattr(self._connections[self._alias], item)
  File "/home/biommcwj/virtualenv/rrb_mnc/3.6/lib/python3.6/site-packages/django/utils/connection.py", line 62, in __getitem__
    conn = self.create_connection(alias)
  File "/home/biommcwj/virtualenv/rrb_mnc/3.6/lib/python3.6/site-packages/django/db/utils.py", line 204, in create_connection
    backend = load_backend(db['ENGINE'])
  File "/home/biommcwj/virtualenv/rrb_mnc/3.6/lib/python3.6/site-packages/django/db/utils.py", line 111, in load_backend
    return import_module('%s.base' % backend_name)
  File "/opt/alt/python36/lib64/python3.6/importlib/__init__.py", line 126, in import_module
    return _bootstrap._gcd_import(name[level:], package, level)
  File "/home/biommcwj/virtualenv/rrb_mnc/3.6/lib/python3.6/site-packages/django/db/backends/sqlite3/base.py", line 73, in <module>
    check_sqlite_version()
  File "/home/biommcwj/virtualenv/rrb_mnc/3.6/lib/python3.6/site-packages/django/db/backends/sqlite3/base.py", line 69, in check_sqlite_version
    'SQLite 3.9.0 or later is required (found %s).' % Database.sqlite_version
django.core.exceptions.ImproperlyConfigured: SQLite 3.9.0 or later is required (found 3.7.0.1).
Traceback (most recent call last):
  File "/home/biommcwj/rrb_mnc/passenger_wsgi.py", line 1, in <module>
    from images.wsgi import  application
  File "/home/biommcwj/rrb_mnc/images/wsgi.py", line 16, in <module>
    application = get_wsgi_application()
  File "/home/biommcwj/virtualenv/rrb_mnc/3.6/lib/python3.6/site-packages/django/core/wsgi.py", line 12, in get_wsgi_application
    django.setup(set_prefix=False)
  File "/home/biommcwj/virtualenv/rrb_mnc/3.6/lib/python3.6/site-packages/django/__init__.py", line 24, in setup
    apps.populate(settings.INSTALLED_APPS)
  File "/home/biommcwj/virtualenv/rrb_mnc/3.6/lib/python3.6/site-packages/django/apps/registry.py", line 83, in populate
    raise RuntimeError("populate() isn't reentrant")
RuntimeError: populate() isn't reentrant
Traceback (most recent call last):
  File "/home/biommcwj/rrb_mnc/passenger_wsgi.py", line 1, in <module>
    from images.wsgi import  application
  File "/home/biommcwj/rrb_mnc/images/wsgi.py", line 16, in <module>
    application = get_wsgi_application()
  File "/home/biommcwj/virtualenv/rrb_mnc/3.6/lib/python3.6/site-packages/django/core/wsgi.py", line 12, in get_wsgi_application
    django.setup(set_prefix=False)
  File "/home/biommcwj/virtualenv/rrb_mnc/3.6/lib/python3.6/site-packages/django/__init__.py", line 24, in setup
    apps.populate(settings.INSTALLED_APPS)
  File "/home/biommcwj/virtualenv/rrb_mnc/3.6/lib/python3.6/site-packages/django/apps/registry.py", line 114, in populate
    app_config.import_models()
  File "/home/biommcwj/virtualenv/rrb_mnc/3.6/lib/python3.6/site-packages/django/apps/config.py", line 301, in import_models
    self.models_module = import_module(models_module_name)
  File "/opt/alt/python36/lib64/python3.6/importlib/__init__.py", line 126, in import_module
    return _bootstrap._gcd_import(name[level:], package, level)
  File "/home/biommcwj/virtualenv/rrb_mnc/3.6/lib/python3.6/site-packages/django/contrib/auth/models.py", line 3, in <module>
    from django.contrib.auth.base_user import AbstractBaseUser, BaseUserManager
  File "/home/biommcwj/virtualenv/rrb_mnc/3.6/lib/python3.6/site-packages/django/contrib/auth/base_user.py", line 48, in <module>
    class AbstractBaseUser(models.Model):
  File "/home/biommcwj/virtualenv/rrb_mnc/3.6/lib/python3.6/site-packages/django/db/models/base.py", line 122, in __new__
    new_class.add_to_class('_meta', Options(meta, app_label))
  File "/home/biommcwj/virtualenv/rrb_mnc/3.6/lib/python3.6/site-packages/django/db/models/base.py", line 326, in add_to_class
    value.contribute_to_class(cls, name)
  File "/home/biommcwj/virtualenv/rrb_mnc/3.6/lib/python3.6/site-packages/django/db/models/options.py", line 207, in contribute_to_class
    self.db_table = truncate_name(self.db_table, connection.ops.max_name_length())
  File "/home/biommcwj/virtualenv/rrb_mnc/3.6/lib/python3.6/site-packages/django/utils/connection.py", line 15, in __getattr__
    return getattr(self._connections[self._alias], item)
  File "/home/biommcwj/virtualenv/rrb_mnc/3.6/lib/python3.6/site-packages/django/utils/connection.py", line 62, in __getitem__
    conn = self.create_connection(alias)
  File "/home/biommcwj/virtualenv/rrb_mnc/3.6/lib/python3.6/site-packages/django/db/utils.py", line 204, in create_connection
    backend = load_backend(db['ENGINE'])
  File "/home/biommcwj/virtualenv/rrb_mnc/3.6/lib/python3.6/site-packages/django/db/utils.py", line 111, in load_backend
    return import_module('%s.base' % backend_name)
  File "/opt/alt/python36/lib64/python3.6/importlib/__init__.py", line 126, in import_module
    return _bootstrap._gcd_import(name[level:], package, level)
  File "/home/biommcwj/virtualenv/rrb_mnc/3.6/lib/python3.6/site-packages/django/db/backends/sqlite3/base.py", line 73, in <module>
    check_sqlite_version()
  File "/home/biommcwj/virtualenv/rrb_mnc/3.6/lib/python3.6/site-packages/django/db/backends/sqlite3/base.py", line 69, in check_sqlite_version
    'SQLite 3.9.0 or later is required (found %s).' % Database.sqlite_version
django.core.exceptions.ImproperlyConfigured: SQLite 3.9.0 or later is required (found 3.7.0.1).
Traceback (most recent call last):
  File "/home/biommcwj/rrb_mnc/passenger_wsgi.py", line 1, in <module>
    from images.wsgi import  application
  File "/home/biommcwj/rrb_mnc/images/wsgi.py", line 16, in <module>
    application = get_wsgi_application()
  File "/home/biommcwj/virtualenv/rrb_mnc/3.6/lib/python3.6/site-packages/django/core/wsgi.py", line 12, in get_wsgi_application
    django.setup(set_prefix=False)
  File "/home/biommcwj/virtualenv/rrb_mnc/3.6/lib/python3.6/site-packages/django/__init__.py", line 24, in setup
    apps.populate(settings.INSTALLED_APPS)
  File "/home/biommcwj/virtualenv/rrb_mnc/3.6/lib/python3.6/site-packages/django/apps/registry.py", line 83, in populate
    raise RuntimeError("populate() isn't reentrant")
RuntimeError: populate() isn't reentrant
Traceback (most recent call last):
  File "/home/biommcwj/rrb_mnc/passenger_wsgi.py", line 1, in <module>
    from images.wsgi import  application
  File "/home/biommcwj/rrb_mnc/images/wsgi.py", line 16, in <module>
    application = get_wsgi_application()
  File "/home/biommcwj/virtualenv/rrb_mnc/3.6/lib/python3.6/site-packages/django/core/wsgi.py", line 12, in get_wsgi_application
    django.setup(set_prefix=False)
  File "/home/biommcwj/virtualenv/rrb_mnc/3.6/lib/python3.6/site-packages/django/__init__.py", line 24, in setup
    apps.populate(settings.INSTALLED_APPS)
  File "/home/biommcwj/virtualenv/rrb_mnc/3.6/lib/python3.6/site-packages/django/apps/registry.py", line 114, in populate
    app_config.import_models()
  File "/home/biommcwj/virtualenv/rrb_mnc/3.6/lib/python3.6/site-packages/django/apps/config.py", line 301, in import_models
    self.models_module = import_module(models_module_name)
  File "/opt/alt/python36/lib64/python3.6/importlib/__init__.py", line 126, in import_module
    return _bootstrap._gcd_import(name[level:], package, level)
  File "/home/biommcwj/virtualenv/rrb_mnc/3.6/lib/python3.6/site-packages/django/contrib/auth/models.py", line 3, in <module>
    from django.contrib.auth.base_user import AbstractBaseUser, BaseUserManager
  File "/home/biommcwj/virtualenv/rrb_mnc/3.6/lib/python3.6/site-packages/django/contrib/auth/base_user.py", line 48, in <module>
    class AbstractBaseUser(models.Model):
  File "/home/biommcwj/virtualenv/rrb_mnc/3.6/lib/python3.6/site-packages/django/db/models/base.py", line 122, in __new__
    new_class.add_to_class('_meta', Options(meta, app_label))
  File "/home/biommcwj/virtualenv/rrb_mnc/3.6/lib/python3.6/site-packages/django/db/models/base.py", line 326, in add_to_class
    value.contribute_to_class(cls, name)
  File "/home/biommcwj/virtualenv/rrb_mnc/3.6/lib/python3.6/site-packages/django/db/models/options.py", line 207, in contribute_to_class
    self.db_table = truncate_name(self.db_table, connection.ops.max_name_length())
  File "/home/biommcwj/virtualenv/rrb_mnc/3.6/lib/python3.6/site-packages/django/utils/connection.py", line 15, in __getattr__
    return getattr(self._connections[self._alias], item)
  File "/home/biommcwj/virtualenv/rrb_mnc/3.6/lib/python3.6/site-packages/django/utils/connection.py", line 62, in __getitem__
    conn = self.create_connection(alias)
  File "/home/biommcwj/virtualenv/rrb_mnc/3.6/lib/python3.6/site-packages/django/db/utils.py", line 204, in create_connection
    backend = load_backend(db['ENGINE'])
  File "/home/biommcwj/virtualenv/rrb_mnc/3.6/lib/python3.6/site-packages/django/db/utils.py", line 111, in load_backend
    return import_module('%s.base' % backend_name)
  File "/opt/alt/python36/lib64/python3.6/importlib/__init__.py", line 126, in import_module
    return _bootstrap._gcd_import(name[level:], package, level)
  File "/home/biommcwj/virtualenv/rrb_mnc/3.6/lib/python3.6/site-packages/django/db/backends/sqlite3/base.py", line 73, in <module>
    check_sqlite_version()
  File "/home/biommcwj/virtualenv/rrb_mnc/3.6/lib/python3.6/site-packages/django/db/backends/sqlite3/base.py", line 69, in check_sqlite_version
    'SQLite 3.9.0 or later is required (found %s).' % Database.sqlite_version
django.core.exceptions.ImproperlyConfigured: SQLite 3.9.0 or later is required (found 3.7.0.1).
Traceback (most recent call last):
  File "/home/biommcwj/virtualenv/rrb_mnc/3.6/lib/python3.6/site-packages/django/db/backends/mysql/base.py", line 15, in <module>
    import MySQLdb as Database
ModuleNotFoundError: No module named 'MySQLdb'

The above exception was the direct cause of the following exception:

Traceback (most recent call last):
  File "/home/biommcwj/rrb_mnc/passenger_wsgi.py", line 1, in <module>
    from images.wsgi import  application
  File "/home/biommcwj/rrb_mnc/images/wsgi.py", line 16, in <module>
    application = get_wsgi_application()
  File "/home/biommcwj/virtualenv/rrb_mnc/3.6/lib/python3.6/site-packages/django/core/wsgi.py", line 12, in get_wsgi_application
    django.setup(set_prefix=False)
  File "/home/biommcwj/virtualenv/rrb_mnc/3.6/lib/python3.6/site-packages/django/__init__.py", line 24, in setup
    apps.populate(settings.INSTALLED_APPS)
  File "/home/biommcwj/virtualenv/rrb_mnc/3.6/lib/python3.6/site-packages/django/apps/registry.py", line 114, in populate
    app_config.import_models()
  File "/home/biommcwj/virtualenv/rrb_mnc/3.6/lib/python3.6/site-packages/django/apps/config.py", line 301, in import_models
    self.models_module = import_module(models_module_name)
  File "/opt/alt/python36/lib64/python3.6/importlib/__init__.py", line 126, in import_module
    return _bootstrap._gcd_import(name[level:], package, level)
  File "/home/biommcwj/virtualenv/rrb_mnc/3.6/lib/python3.6/site-packages/django/contrib/auth/models.py", line 3, in <module>
    from django.contrib.auth.base_user import AbstractBaseUser, BaseUserManager
  File "/home/biommcwj/virtualenv/rrb_mnc/3.6/lib/python3.6/site-packages/django/contrib/auth/base_user.py", line 48, in <module>
    class AbstractBaseUser(models.Model):
  File "/home/biommcwj/virtualenv/rrb_mnc/3.6/lib/python3.6/site-packages/django/db/models/base.py", line 122, in __new__
    new_class.add_to_class('_meta', Options(meta, app_label))
  File "/home/biommcwj/virtualenv/rrb_mnc/3.6/lib/python3.6/site-packages/django/db/models/base.py", line 326, in add_to_class
    value.contribute_to_class(cls, name)
  File "/home/biommcwj/virtualenv/rrb_mnc/3.6/lib/python3.6/site-packages/django/db/models/options.py", line 207, in contribute_to_class
    self.db_table = truncate_name(self.db_table, connection.ops.max_name_length())
  File "/home/biommcwj/virtualenv/rrb_mnc/3.6/lib/python3.6/site-packages/django/utils/connection.py", line 15, in __getattr__
    return getattr(self._connections[self._alias], item)
  File "/home/biommcwj/virtualenv/rrb_mnc/3.6/lib/python3.6/site-packages/django/utils/connection.py", line 62, in __getitem__
    conn = self.create_connection(alias)
  File "/home/biommcwj/virtualenv/rrb_mnc/3.6/lib/python3.6/site-packages/django/db/utils.py", line 204, in create_connection
    backend = load_backend(db['ENGINE'])
  File "/home/biommcwj/virtualenv/rrb_mnc/3.6/lib/python3.6/site-packages/django/db/utils.py", line 111, in load_backend
    return import_module('%s.base' % backend_name)
  File "/opt/alt/python36/lib64/python3.6/importlib/__init__.py", line 126, in import_module
    return _bootstrap._gcd_import(name[level:], package, level)
  File "/home/biommcwj/virtualenv/rrb_mnc/3.6/lib/python3.6/site-packages/django/db/backends/mysql/base.py", line 20, in <module>
    ) from err
django.core.exceptions.ImproperlyConfigured: Error loading MySQLdb module.
Did you install mysqlclient?
Traceback (most recent call last):
  File "/home/biommcwj/virtualenv/rrb_mnc/3.6/lib/python3.6/site-packages/django/db/backends/mysql/base.py", line 15, in <module>
    import MySQLdb as Database
ModuleNotFoundError: No module named 'MySQLdb'

The above exception was the direct cause of the following exception:

Traceback (most recent call last):
  File "/home/biommcwj/rrb_mnc/passenger_wsgi.py", line 1, in <module>
    from images.wsgi import  application
  File "/home/biommcwj/rrb_mnc/images/wsgi.py", line 16, in <module>
    application = get_wsgi_application()
  File "/home/biommcwj/virtualenv/rrb_mnc/3.6/lib/python3.6/site-packages/django/core/wsgi.py", line 12, in get_wsgi_application
    django.setup(set_prefix=False)
  File "/home/biommcwj/virtualenv/rrb_mnc/3.6/lib/python3.6/site-packages/django/__init__.py", line 24, in setup
    apps.populate(settings.INSTALLED_APPS)
  File "/home/biommcwj/virtualenv/rrb_mnc/3.6/lib/python3.6/site-packages/django/apps/registry.py", line 114, in populate
    app_config.import_models()
  File "/home/biommcwj/virtualenv/rrb_mnc/3.6/lib/python3.6/site-packages/django/apps/config.py", line 301, in import_models
    self.models_module = import_module(models_module_name)
  File "/opt/alt/python36/lib64/python3.6/importlib/__init__.py", line 126, in import_module
    return _bootstrap._gcd_import(name[level:], package, level)
  File "/home/biommcwj/virtualenv/rrb_mnc/3.6/lib/python3.6/site-packages/django/contrib/auth/models.py", line 3, in <module>
    from django.contrib.auth.base_user import AbstractBaseUser, BaseUserManager
  File "/home/biommcwj/virtualenv/rrb_mnc/3.6/lib/python3.6/site-packages/django/contrib/auth/base_user.py", line 48, in <module>
    class AbstractBaseUser(models.Model):
  File "/home/biommcwj/virtualenv/rrb_mnc/3.6/lib/python3.6/site-packages/django/db/models/base.py", line 122, in __new__
    new_class.add_to_class('_meta', Options(meta, app_label))
  File "/home/biommcwj/virtualenv/rrb_mnc/3.6/lib/python3.6/site-packages/django/db/models/base.py", line 326, in add_to_class
    value.contribute_to_class(cls, name)
  File "/home/biommcwj/virtualenv/rrb_mnc/3.6/lib/python3.6/site-packages/django/db/models/options.py", line 207, in contribute_to_class
    self.db_table = truncate_name(self.db_table, connection.ops.max_name_length())
  File "/home/biommcwj/virtualenv/rrb_mnc/3.6/lib/python3.6/site-packages/django/utils/connection.py", line 15, in __getattr__
    return getattr(self._connections[self._alias], item)
  File "/home/biommcwj/virtualenv/rrb_mnc/3.6/lib/python3.6/site-packages/django/utils/connection.py", line 62, in __getitem__
    conn = self.create_connection(alias)
  File "/home/biommcwj/virtualenv/rrb_mnc/3.6/lib/python3.6/site-packages/django/db/utils.py", line 204, in create_connection
    backend = load_backend(db['ENGINE'])
  File "/home/biommcwj/virtualenv/rrb_mnc/3.6/lib/python3.6/site-packages/django/db/utils.py", line 111, in load_backend
    return import_module('%s.base' % backend_name)
  File "/opt/alt/python36/lib64/python3.6/importlib/__init__.py", line 126, in import_module
    return _bootstrap._gcd_import(name[level:], package, level)
  File "/home/biommcwj/virtualenv/rrb_mnc/3.6/lib/python3.6/site-packages/django/db/backends/mysql/base.py", line 20, in <module>
    ) from err
django.core.exceptions.ImproperlyConfigured: Error loading MySQLdb module.
Did you install mysqlclient?
Traceback (most recent call last):
  File "/home/biommcwj/rrb_mnc/passenger_wsgi.py", line 1, in <module>
    from images.wsgi import  application
  File "/home/biommcwj/rrb_mnc/images/wsgi.py", line 16, in <module>
    application = get_wsgi_application()
  File "/home/biommcwj/virtualenv/rrb_mnc/3.6/lib/python3.6/site-packages/django/core/wsgi.py", line 12, in get_wsgi_application
    django.setup(set_prefix=False)
  File "/home/biommcwj/virtualenv/rrb_mnc/3.6/lib/python3.6/site-packages/django/__init__.py", line 24, in setup
    apps.populate(settings.INSTALLED_APPS)
  File "/home/biommcwj/virtualenv/rrb_mnc/3.6/lib/python3.6/site-packages/django/apps/registry.py", line 83, in populate
    raise RuntimeError("populate() isn't reentrant")
RuntimeError: populate() isn't reentrant
Not Found: /static/assets/css/bootstrap.min.css
Not Found: /static/assets/css/blog.css
Not Found: /static/assets/css/bootstrap.min.css
Not Found: /static/assets/css/blog.css
Not Found: /static/assets/css/blog.css
Not Found: /static/assets/css/bootstrap.min.css
Not Found: /static/assets/css/bootstrap.min.css
Not Found: /static/assets/css/blog.css
Not Found: /static/assets/css/bootstrap.min.css
Not Found: /static/assets/css/blog.css
Not Found: /static/assets/css/bootstrap.min.css
Not Found: /static/assets/css/blog.css
Not Found: /static/assets/css/bootstrap.min.css
Not Found: /static/assets/css/blog.css
Not Found: /static/assets/css/bootstrap.min.css
Not Found: /static/assets/css/blog.css
Not Found: /static/assets/css/blog.css
Not Found: /static/assets/css/bootstrap.min.css
Not Found: /static/assets/css/blog.css
Not Found: /static/admin/css/base.css
Not Found: /static/admin/css/nav_sidebar.css
Not Found: /static/admin/js/nav_sidebar.js
Not Found: /static/admin/css/responsive.css
Not Found: /static/admin/css/login.css
Internal Server Error: /admin/main/image/add/
Traceback (most recent call last):
  File "/home/biommcwj/virtualenv/rrb_mnc/3.6/lib/python3.6/site-packages/django/core/handlers/exception.py", line 47, in inner
    response = get_response(request)
  File "/home/biommcwj/virtualenv/rrb_mnc/3.6/lib/python3.6/site-packages/django/core/handlers/base.py", line 181, in _get_response
    response = wrapped_callback(request, *callback_args, **callback_kwargs)
  File "/home/biommcwj/virtualenv/rrb_mnc/3.6/lib/python3.6/site-packages/django/contrib/admin/options.py", line 616, in wrapper
    return self.admin_site.admin_view(view)(*args, **kwargs)
  File "/home/biommcwj/virtualenv/rrb_mnc/3.6/lib/python3.6/site-packages/django/utils/decorators.py", line 130, in _wrapped_view
    response = view_func(request, *args, **kwargs)
  File "/home/biommcwj/virtualenv/rrb_mnc/3.6/lib/python3.6/site-packages/django/views/decorators/cache.py", line 44, in _wrapped_view_func
    response = view_func(request, *args, **kwargs)
  File "/home/biommcwj/virtualenv/rrb_mnc/3.6/lib/python3.6/site-packages/django/contrib/admin/sites.py", line 232, in inner
    return view(request, *args, **kwargs)
  File "/home/biommcwj/virtualenv/rrb_mnc/3.6/lib/python3.6/site-packages/django/contrib/admin/options.py", line 1657, in add_view
    return self.changeform_view(request, None, form_url, extra_context)
  File "/home/biommcwj/virtualenv/rrb_mnc/3.6/lib/python3.6/site-packages/django/utils/decorators.py", line 43, in _wrapper
    return bound_method(*args, **kwargs)
  File "/home/biommcwj/virtualenv/rrb_mnc/3.6/lib/python3.6/site-packages/django/utils/decorators.py", line 130, in _wrapped_view
    response = view_func(request, *args, **kwargs)
  File "/home/biommcwj/virtualenv/rrb_mnc/3.6/lib/python3.6/site-packages/django/contrib/admin/options.py", line 1540, in changeform_view
    return self._changeform_view(request, object_id, form_url, extra_context)
  File "/home/biommcwj/virtualenv/rrb_mnc/3.6/lib/python3.6/site-packages/django/contrib/admin/options.py", line 1586, in _changeform_view
    self.save_model(request, new_object, form, not add)
  File "/home/biommcwj/virtualenv/rrb_mnc/3.6/lib/python3.6/site-packages/django/contrib/admin/options.py", line 1099, in save_model
    obj.save()
  File "/home/biommcwj/rrb_mnc/main/models.py", line 77, in save
    self.slug = slugify('{} {}'.format(self.category.title, self.uniqueId))
AttributeError: 'NoneType' object has no attribute 'title'
Not Found: /uploads/default_land.jpg
Not Found: /uploads/default_tall.jpg
Not Found: /uploads/default_land.jpg
Not Found: /uploads/default_land.jpg
Internal Server Error: /
Traceback (most recent call last):
  File "/home/biommcwj/virtualenv/rrb_mnc/3.6/lib/python3.6/site-packages/django/core/handlers/exception.py", line 47, in inner
    response = get_response(request)
  File "/home/biommcwj/virtualenv/rrb_mnc/3.6/lib/python3.6/site-packages/django/core/handlers/base.py", line 181, in _get_response
    response = wrapped_callback(request, *callback_args, **callback_kwargs)
  File "/home/biommcwj/rrb_mnc/main/views.py", line 12, in home
    return render(request, 'main/index.html', context)
  File "/home/biommcwj/virtualenv/rrb_mnc/3.6/lib/python3.6/site-packages/django/shortcuts.py", line 19, in render
    content = loader.render_to_string(template_name, context, request, using=using)
  File "/home/biommcwj/virtualenv/rrb_mnc/3.6/lib/python3.6/site-packages/django/template/loader.py", line 62, in render_to_string
    return template.render(context, request)
  File "/home/biommcwj/virtualenv/rrb_mnc/3.6/lib/python3.6/site-packages/django/template/backends/django.py", line 61, in render
    return self.template.render(context)
  File "/home/biommcwj/virtualenv/rrb_mnc/3.6/lib/python3.6/site-packages/django/template/base.py", line 170, in render
    return self._render(context)
  File "/home/biommcwj/virtualenv/rrb_mnc/3.6/lib/python3.6/site-packages/django/template/base.py", line 162, in _render
    return self.nodelist.render(context)
  File "/home/biommcwj/virtualenv/rrb_mnc/3.6/lib/python3.6/site-packages/django/template/base.py", line 938, in render
    bit = node.render_annotated(context)
  File "/home/biommcwj/virtualenv/rrb_mnc/3.6/lib/python3.6/site-packages/django/template/base.py", line 905, in render_annotated
    return self.render(context)
  File "/home/biommcwj/virtualenv/rrb_mnc/3.6/lib/python3.6/site-packages/django/template/defaulttags.py", line 446, in render
    url = reverse(view_name, args=args, kwargs=kwargs, current_app=current_app)
  File "/home/biommcwj/virtualenv/rrb_mnc/3.6/lib/python3.6/site-packages/django/urls/base.py", line 86, in reverse
    return resolver._reverse_with_prefix(view, prefix, *args, **kwargs)
  File "/home/biommcwj/virtualenv/rrb_mnc/3.6/lib/python3.6/site-packages/django/urls/resolvers.py", line 694, in _reverse_with_prefix
    raise NoReverseMatch(msg)
django.urls.exceptions.NoReverseMatch: Reverse for 'about' not found. 'about' is not a valid view function or pattern name.
Internal Server Error: /
Traceback (most recent call last):
  File "/home/biommcwj/virtualenv/rrb_mnc/3.6/lib/python3.6/site-packages/django/core/handlers/exception.py", line 47, in inner
    response = get_response(request)
  File "/home/biommcwj/virtualenv/rrb_mnc/3.6/lib/python3.6/site-packages/django/core/handlers/base.py", line 181, in _get_response
    response = wrapped_callback(request, *callback_args, **callback_kwargs)
  File "/home/biommcwj/rrb_mnc/main/views.py", line 12, in home
    return render(request, 'main/index.html', context)
  File "/home/biommcwj/virtualenv/rrb_mnc/3.6/lib/python3.6/site-packages/django/shortcuts.py", line 19, in render
    content = loader.render_to_string(template_name, context, request, using=using)
  File "/home/biommcwj/virtualenv/rrb_mnc/3.6/lib/python3.6/site-packages/django/template/loader.py", line 62, in render_to_string
    return template.render(context, request)
  File "/home/biommcwj/virtualenv/rrb_mnc/3.6/lib/python3.6/site-packages/django/template/backends/django.py", line 61, in render
    return self.template.render(context)
  File "/home/biommcwj/virtualenv/rrb_mnc/3.6/lib/python3.6/site-packages/django/template/base.py", line 170, in render
    return self._render(context)
  File "/home/biommcwj/virtualenv/rrb_mnc/3.6/lib/python3.6/site-packages/django/template/base.py", line 162, in _render
    return self.nodelist.render(context)
  File "/home/biommcwj/virtualenv/rrb_mnc/3.6/lib/python3.6/site-packages/django/template/base.py", line 938, in render
    bit = node.render_annotated(context)
  File "/home/biommcwj/virtualenv/rrb_mnc/3.6/lib/python3.6/site-packages/django/template/base.py", line 905, in render_annotated
    return self.render(context)
  File "/home/biommcwj/virtualenv/rrb_mnc/3.6/lib/python3.6/site-packages/django/template/defaulttags.py", line 446, in render
    url = reverse(view_name, args=args, kwargs=kwargs, current_app=current_app)
  File "/home/biommcwj/virtualenv/rrb_mnc/3.6/lib/python3.6/site-packages/django/urls/base.py", line 86, in reverse
    return resolver._reverse_with_prefix(view, prefix, *args, **kwargs)
  File "/home/biommcwj/virtualenv/rrb_mnc/3.6/lib/python3.6/site-packages/django/urls/resolvers.py", line 694, in _reverse_with_prefix
    raise NoReverseMatch(msg)
django.urls.exceptions.NoReverseMatch: Reverse for 'admin' not found. 'admin' is not a valid view function or pattern name.
Internal Server Error: /
Traceback (most recent call last):
  File "/home/biommcwj/virtualenv/rrb_mnc/3.6/lib/python3.6/site-packages/django/core/handlers/exception.py", line 47, in inner
    response = get_response(request)
  File "/home/biommcwj/virtualenv/rrb_mnc/3.6/lib/python3.6/site-packages/django/core/handlers/base.py", line 181, in _get_response
    response = wrapped_callback(request, *callback_args, **callback_kwargs)
  File "/home/biommcwj/rrb_mnc/main/views.py", line 12, in home
    return render(request, 'main/index.html', context)
  File "/home/biommcwj/virtualenv/rrb_mnc/3.6/lib/python3.6/site-packages/django/shortcuts.py", line 19, in render
    content = loader.render_to_string(template_name, context, request, using=using)
  File "/home/biommcwj/virtualenv/rrb_mnc/3.6/lib/python3.6/site-packages/django/template/loader.py", line 62, in render_to_string
    return template.render(context, request)
  File "/home/biommcwj/virtualenv/rrb_mnc/3.6/lib/python3.6/site-packages/django/template/backends/django.py", line 61, in render
    return self.template.render(context)
  File "/home/biommcwj/virtualenv/rrb_mnc/3.6/lib/python3.6/site-packages/django/template/base.py", line 170, in render
    return self._render(context)
  File "/home/biommcwj/virtualenv/rrb_mnc/3.6/lib/python3.6/site-packages/django/template/base.py", line 162, in _render
    return self.nodelist.render(context)
  File "/home/biommcwj/virtualenv/rrb_mnc/3.6/lib/python3.6/site-packages/django/template/base.py", line 938, in render
    bit = node.render_annotated(context)
  File "/home/biommcwj/virtualenv/rrb_mnc/3.6/lib/python3.6/site-packages/django/template/base.py", line 905, in render_annotated
    return self.render(context)
  File "/home/biommcwj/virtualenv/rrb_mnc/3.6/lib/python3.6/site-packages/django/template/defaulttags.py", line 446, in render
    url = reverse(view_name, args=args, kwargs=kwargs, current_app=current_app)
  File "/home/biommcwj/virtualenv/rrb_mnc/3.6/lib/python3.6/site-packages/django/urls/base.py", line 86, in reverse
    return resolver._reverse_with_prefix(view, prefix, *args, **kwargs)
  File "/home/biommcwj/virtualenv/rrb_mnc/3.6/lib/python3.6/site-packages/django/urls/resolvers.py", line 694, in _reverse_with_prefix
    raise NoReverseMatch(msg)
django.urls.exceptions.NoReverseMatch: Reverse for 'admin' not found. 'admin' is not a valid view function or pattern name.
Internal Server Error: /
Traceback (most recent call last):
  File "/home/biommcwj/virtualenv/rrb_mnc/3.6/lib/python3.6/site-packages/django/core/handlers/exception.py", line 47, in inner
    response = get_response(request)
  File "/home/biommcwj/virtualenv/rrb_mnc/3.6/lib/python3.6/site-packages/django/core/handlers/base.py", line 181, in _get_response
    response = wrapped_callback(request, *callback_args, **callback_kwargs)
  File "/home/biommcwj/rrb_mnc/main/views.py", line 12, in home
    return render(request, 'main/index.html', context)
  File "/home/biommcwj/virtualenv/rrb_mnc/3.6/lib/python3.6/site-packages/django/shortcuts.py", line 19, in render
    content = loader.render_to_string(template_name, context, request, using=using)
  File "/home/biommcwj/virtualenv/rrb_mnc/3.6/lib/python3.6/site-packages/django/template/loader.py", line 62, in render_to_string
    return template.render(context, request)
  File "/home/biommcwj/virtualenv/rrb_mnc/3.6/lib/python3.6/site-packages/django/template/backends/django.py", line 61, in render
    return self.template.render(context)
  File "/home/biommcwj/virtualenv/rrb_mnc/3.6/lib/python3.6/site-packages/django/template/base.py", line 170, in render
    return self._render(context)
  File "/home/biommcwj/virtualenv/rrb_mnc/3.6/lib/python3.6/site-packages/django/template/base.py", line 162, in _render
    return self.nodelist.render(context)
  File "/home/biommcwj/virtualenv/rrb_mnc/3.6/lib/python3.6/site-packages/django/template/base.py", line 938, in render
    bit = node.render_annotated(context)
  File "/home/biommcwj/virtualenv/rrb_mnc/3.6/lib/python3.6/site-packages/django/template/base.py", line 905, in render_annotated
    return self.render(context)
  File "/home/biommcwj/virtualenv/rrb_mnc/3.6/lib/python3.6/site-packages/django/template/defaulttags.py", line 446, in render
    url = reverse(view_name, args=args, kwargs=kwargs, current_app=current_app)
  File "/home/biommcwj/virtualenv/rrb_mnc/3.6/lib/python3.6/site-packages/django/urls/base.py", line 86, in reverse
    return resolver._reverse_with_prefix(view, prefix, *args, **kwargs)
  File "/home/biommcwj/virtualenv/rrb_mnc/3.6/lib/python3.6/site-packages/django/urls/resolvers.py", line 694, in _reverse_with_prefix
    raise NoReverseMatch(msg)
django.urls.exceptions.NoReverseMatch: Reverse for 'admin' not found. 'admin' is not a valid view function or pattern name.
Internal Server Error: /
Traceback (most recent call last):
  File "/home/biommcwj/virtualenv/rrb_mnc/3.6/lib/python3.6/site-packages/django/core/handlers/exception.py", line 47, in inner
    response = get_response(request)
  File "/home/biommcwj/virtualenv/rrb_mnc/3.6/lib/python3.6/site-packages/django/core/handlers/base.py", line 181, in _get_response
    response = wrapped_callback(request, *callback_args, **callback_kwargs)
  File "/home/biommcwj/rrb_mnc/main/views.py", line 12, in home
    return render(request, 'main/index.html', context)
  File "/home/biommcwj/virtualenv/rrb_mnc/3.6/lib/python3.6/site-packages/django/shortcuts.py", line 19, in render
    content = loader.render_to_string(template_name, context, request, using=using)
  File "/home/biommcwj/virtualenv/rrb_mnc/3.6/lib/python3.6/site-packages/django/template/loader.py", line 62, in render_to_string
    return template.render(context, request)
  File "/home/biommcwj/virtualenv/rrb_mnc/3.6/lib/python3.6/site-packages/django/template/backends/django.py", line 61, in render
    return self.template.render(context)
  File "/home/biommcwj/virtualenv/rrb_mnc/3.6/lib/python3.6/site-packages/django/template/base.py", line 170, in render
    return self._render(context)
  File "/home/biommcwj/virtualenv/rrb_mnc/3.6/lib/python3.6/site-packages/django/template/base.py", line 162, in _render
    return self.nodelist.render(context)
  File "/home/biommcwj/virtualenv/rrb_mnc/3.6/lib/python3.6/site-packages/django/template/base.py", line 938, in render
    bit = node.render_annotated(context)
  File "/home/biommcwj/virtualenv/rrb_mnc/3.6/lib/python3.6/site-packages/django/template/base.py", line 905, in render_annotated
    return self.render(context)
  File "/home/biommcwj/virtualenv/rrb_mnc/3.6/lib/python3.6/site-packages/django/template/defaulttags.py", line 446, in render
    url = reverse(view_name, args=args, kwargs=kwargs, current_app=current_app)
  File "/home/biommcwj/virtualenv/rrb_mnc/3.6/lib/python3.6/site-packages/django/urls/base.py", line 86, in reverse
    return resolver._reverse_with_prefix(view, prefix, *args, **kwargs)
  File "/home/biommcwj/virtualenv/rrb_mnc/3.6/lib/python3.6/site-packages/django/urls/resolvers.py", line 694, in _reverse_with_prefix
    raise NoReverseMatch(msg)
django.urls.exceptions.NoReverseMatch: Reverse for 'about' not found. 'about' is not a valid view function or pattern name.
Internal Server Error: /
Traceback (most recent call last):
  File "/home/biommcwj/virtualenv/rrb_mnc/3.6/lib/python3.6/site-packages/django/core/handlers/exception.py", line 47, in inner
    response = get_response(request)
  File "/home/biommcwj/virtualenv/rrb_mnc/3.6/lib/python3.6/site-packages/django/core/handlers/base.py", line 181, in _get_response
    response = wrapped_callback(request, *callback_args, **callback_kwargs)
  File "/home/biommcwj/rrb_mnc/main/views.py", line 12, in home
    return render(request, 'main/index.html', context)
  File "/home/biommcwj/virtualenv/rrb_mnc/3.6/lib/python3.6/site-packages/django/shortcuts.py", line 19, in render
    content = loader.render_to_string(template_name, context, request, using=using)
  File "/home/biommcwj/virtualenv/rrb_mnc/3.6/lib/python3.6/site-packages/django/template/loader.py", line 62, in render_to_string
    return template.render(context, request)
  File "/home/biommcwj/virtualenv/rrb_mnc/3.6/lib/python3.6/site-packages/django/template/backends/django.py", line 61, in render
    return self.template.render(context)
  File "/home/biommcwj/virtualenv/rrb_mnc/3.6/lib/python3.6/site-packages/django/template/base.py", line 170, in render
    return self._render(context)
  File "/home/biommcwj/virtualenv/rrb_mnc/3.6/lib/python3.6/site-packages/django/template/base.py", line 162, in _render
    return self.nodelist.render(context)
  File "/home/biommcwj/virtualenv/rrb_mnc/3.6/lib/python3.6/site-packages/django/template/base.py", line 938, in render
    bit = node.render_annotated(context)
  File "/home/biommcwj/virtualenv/rrb_mnc/3.6/lib/python3.6/site-packages/django/template/base.py", line 905, in render_annotated
    return self.render(context)
  File "/home/biommcwj/virtualenv/rrb_mnc/3.6/lib/python3.6/site-packages/django/template/defaulttags.py", line 446, in render
    url = reverse(view_name, args=args, kwargs=kwargs, current_app=current_app)
  File "/home/biommcwj/virtualenv/rrb_mnc/3.6/lib/python3.6/site-packages/django/urls/base.py", line 86, in reverse
    return resolver._reverse_with_prefix(view, prefix, *args, **kwargs)
  File "/home/biommcwj/virtualenv/rrb_mnc/3.6/lib/python3.6/site-packages/django/urls/resolvers.py", line 694, in _reverse_with_prefix
    raise NoReverseMatch(msg)
django.urls.exceptions.NoReverseMatch: Reverse for 'about' not found. 'about' is not a valid view function or pattern name.
Internal Server Error: /
Traceback (most recent call last):
  File "/home/biommcwj/virtualenv/rrb_mnc/3.6/lib/python3.6/site-packages/django/core/handlers/exception.py", line 47, in inner
    response = get_response(request)
  File "/home/biommcwj/virtualenv/rrb_mnc/3.6/lib/python3.6/site-packages/django/core/handlers/base.py", line 181, in _get_response
    response = wrapped_callback(request, *callback_args, **callback_kwargs)
  File "/home/biommcwj/rrb_mnc/main/views.py", line 12, in home
    return render(request, 'main/index.html', context)
  File "/home/biommcwj/virtualenv/rrb_mnc/3.6/lib/python3.6/site-packages/django/shortcuts.py", line 19, in render
    content = loader.render_to_string(template_name, context, request, using=using)
  File "/home/biommcwj/virtualenv/rrb_mnc/3.6/lib/python3.6/site-packages/django/template/loader.py", line 62, in render_to_string
    return template.render(context, request)
  File "/home/biommcwj/virtualenv/rrb_mnc/3.6/lib/python3.6/site-packages/django/template/backends/django.py", line 61, in render
    return self.template.render(context)
  File "/home/biommcwj/virtualenv/rrb_mnc/3.6/lib/python3.6/site-packages/django/template/base.py", line 170, in render
    return self._render(context)
  File "/home/biommcwj/virtualenv/rrb_mnc/3.6/lib/python3.6/site-packages/django/template/base.py", line 162, in _render
    return self.nodelist.render(context)
  File "/home/biommcwj/virtualenv/rrb_mnc/3.6/lib/python3.6/site-packages/django/template/base.py", line 938, in render
    bit = node.render_annotated(context)
  File "/home/biommcwj/virtualenv/rrb_mnc/3.6/lib/python3.6/site-packages/django/template/base.py", line 905, in render_annotated
    return self.render(context)
  File "/home/biommcwj/virtualenv/rrb_mnc/3.6/lib/python3.6/site-packages/django/template/defaulttags.py", line 446, in render
    url = reverse(view_name, args=args, kwargs=kwargs, current_app=current_app)
  File "/home/biommcwj/virtualenv/rrb_mnc/3.6/lib/python3.6/site-packages/django/urls/base.py", line 86, in reverse
    return resolver._reverse_with_prefix(view, prefix, *args, **kwargs)
  File "/home/biommcwj/virtualenv/rrb_mnc/3.6/lib/python3.6/site-packages/django/urls/resolvers.py", line 694, in _reverse_with_prefix
    raise NoReverseMatch(msg)
django.urls.exceptions.NoReverseMatch: Reverse for 'about' not found. 'about' is not a valid view function or pattern name.
Not Found: /favicon.ico
Internal Server Error: /
Traceback (most recent call last):
  File "/home/biommcwj/virtualenv/rrb_mnc/3.6/lib/python3.6/site-packages/django/template/backends/django.py", line 61, in render
    return self.template.render(context)
  File "/home/biommcwj/virtualenv/rrb_mnc/3.6/lib/python3.6/site-packages/django/template/base.py", line 170, in render
    return self._render(context)
  File "/home/biommcwj/virtualenv/rrb_mnc/3.6/lib/python3.6/site-packages/django/template/base.py", line 162, in _render
    return self.nodelist.render(context)
  File "/home/biommcwj/virtualenv/rrb_mnc/3.6/lib/python3.6/site-packages/django/template/base.py", line 938, in render
    bit = node.render_annotated(context)
  File "/home/biommcwj/virtualenv/rrb_mnc/3.6/lib/python3.6/site-packages/django/template/base.py", line 905, in render_annotated
    return self.render(context)
  File "/home/biommcwj/virtualenv/rrb_mnc/3.6/lib/python3.6/site-packages/django/template/loader_tags.py", line 183, in render
    template = context.template.engine.select_template(template_name)
  File "/home/biommcwj/virtualenv/rrb_mnc/3.6/lib/python3.6/site-packages/django/template/engine.py", line 180, in select_template
    raise TemplateDoesNotExist(', '.join(not_found))
django.template.exceptions.TemplateDoesNotExist: header.html

The above exception was the direct cause of the following exception:

Traceback (most recent call last):
  File "/home/biommcwj/virtualenv/rrb_mnc/3.6/lib/python3.6/site-packages/django/core/handlers/exception.py", line 47, in inner
    response = get_response(request)
  File "/home/biommcwj/virtualenv/rrb_mnc/3.6/lib/python3.6/site-packages/django/core/handlers/base.py", line 181, in _get_response
    response = wrapped_callback(request, *callback_args, **callback_kwargs)
  File "/home/biommcwj/rrb_mnc/main/views.py", line 12, in home
    return render(request, 'main/index.html', context)
  File "/home/biommcwj/virtualenv/rrb_mnc/3.6/lib/python3.6/site-packages/django/shortcuts.py", line 19, in render
    content = loader.render_to_string(template_name, context, request, using=using)
  File "/home/biommcwj/virtualenv/rrb_mnc/3.6/lib/python3.6/site-packages/django/template/loader.py", line 62, in render_to_string
    return template.render(context, request)
  File "/home/biommcwj/virtualenv/rrb_mnc/3.6/lib/python3.6/site-packages/django/template/backends/django.py", line 63, in render
    reraise(exc, self.backend)
  File "/home/biommcwj/virtualenv/rrb_mnc/3.6/lib/python3.6/site-packages/django/template/backends/django.py", line 84, in reraise
    raise new from exc
django.template.exceptions.TemplateDoesNotExist: header.html
Internal Server Error: /
Traceback (most recent call last):
  File "/home/biommcwj/virtualenv/rrb_mnc/3.6/lib/python3.6/site-packages/django/template/backends/django.py", line 61, in render
    return self.template.render(context)
  File "/home/biommcwj/virtualenv/rrb_mnc/3.6/lib/python3.6/site-packages/django/template/base.py", line 170, in render
    return self._render(context)
  File "/home/biommcwj/virtualenv/rrb_mnc/3.6/lib/python3.6/site-packages/django/template/base.py", line 162, in _render
    return self.nodelist.render(context)
  File "/home/biommcwj/virtualenv/rrb_mnc/3.6/lib/python3.6/site-packages/django/template/base.py", line 938, in render
    bit = node.render_annotated(context)
  File "/home/biommcwj/virtualenv/rrb_mnc/3.6/lib/python3.6/site-packages/django/template/base.py", line 905, in render_annotated
    return self.render(context)
  File "/home/biommcwj/virtualenv/rrb_mnc/3.6/lib/python3.6/site-packages/django/template/loader_tags.py", line 183, in render
    template = context.template.engine.select_template(template_name)
  File "/home/biommcwj/virtualenv/rrb_mnc/3.6/lib/python3.6/site-packages/django/template/engine.py", line 180, in select_template
    raise TemplateDoesNotExist(', '.join(not_found))
django.template.exceptions.TemplateDoesNotExist: header.html

The above exception was the direct cause of the following exception:

Traceback (most recent call last):
  File "/home/biommcwj/virtualenv/rrb_mnc/3.6/lib/python3.6/site-packages/django/core/handlers/exception.py", line 47, in inner
    response = get_response(request)
  File "/home/biommcwj/virtualenv/rrb_mnc/3.6/lib/python3.6/site-packages/django/core/handlers/base.py", line 181, in _get_response
    response = wrapped_callback(request, *callback_args, **callback_kwargs)
  File "/home/biommcwj/rrb_mnc/main/views.py", line 12, in home
    return render(request, 'main/index.html', context)
  File "/home/biommcwj/virtualenv/rrb_mnc/3.6/lib/python3.6/site-packages/django/shortcuts.py", line 19, in render
    content = loader.render_to_string(template_name, context, request, using=using)
  File "/home/biommcwj/virtualenv/rrb_mnc/3.6/lib/python3.6/site-packages/django/template/loader.py", line 62, in render_to_string
    return template.render(context, request)
  File "/home/biommcwj/virtualenv/rrb_mnc/3.6/lib/python3.6/site-packages/django/template/backends/django.py", line 63, in render
    reraise(exc, self.backend)
  File "/home/biommcwj/virtualenv/rrb_mnc/3.6/lib/python3.6/site-packages/django/template/backends/django.py", line 84, in reraise
    raise new from exc
django.template.exceptions.TemplateDoesNotExist: header.html
Internal Server Error: /
Traceback (most recent call last):
  File "/home/biommcwj/virtualenv/rrb_mnc/3.6/lib/python3.6/site-packages/django/template/backends/django.py", line 61, in render
    return self.template.render(context)
  File "/home/biommcwj/virtualenv/rrb_mnc/3.6/lib/python3.6/site-packages/django/template/base.py", line 170, in render
    return self._render(context)
  File "/home/biommcwj/virtualenv/rrb_mnc/3.6/lib/python3.6/site-packages/django/template/base.py", line 162, in _render
    return self.nodelist.render(context)
  File "/home/biommcwj/virtualenv/rrb_mnc/3.6/lib/python3.6/site-packages/django/template/base.py", line 938, in render
    bit = node.render_annotated(context)
  File "/home/biommcwj/virtualenv/rrb_mnc/3.6/lib/python3.6/site-packages/django/template/base.py", line 905, in render_annotated
    return self.render(context)
  File "/home/biommcwj/virtualenv/rrb_mnc/3.6/lib/python3.6/site-packages/django/template/loader_tags.py", line 183, in render
    template = context.template.engine.select_template(template_name)
  File "/home/biommcwj/virtualenv/rrb_mnc/3.6/lib/python3.6/site-packages/django/template/engine.py", line 180, in select_template
    raise TemplateDoesNotExist(', '.join(not_found))
django.template.exceptions.TemplateDoesNotExist: header.html

The above exception was the direct cause of the following exception:

Traceback (most recent call last):
  File "/home/biommcwj/virtualenv/rrb_mnc/3.6/lib/python3.6/site-packages/django/core/handlers/exception.py", line 47, in inner
    response = get_response(request)
  File "/home/biommcwj/virtualenv/rrb_mnc/3.6/lib/python3.6/site-packages/django/core/handlers/base.py", line 181, in _get_response
    response = wrapped_callback(request, *callback_args, **callback_kwargs)
  File "/home/biommcwj/rrb_mnc/main/views.py", line 12, in home
    return render(request, 'main/index.html', context)
  File "/home/biommcwj/virtualenv/rrb_mnc/3.6/lib/python3.6/site-packages/django/shortcuts.py", line 19, in render
    content = loader.render_to_string(template_name, context, request, using=using)
  File "/home/biommcwj/virtualenv/rrb_mnc/3.6/lib/python3.6/site-packages/django/template/loader.py", line 62, in render_to_string
    return template.render(context, request)
  File "/home/biommcwj/virtualenv/rrb_mnc/3.6/lib/python3.6/site-packages/django/template/backends/django.py", line 63, in render
    reraise(exc, self.backend)
  File "/home/biommcwj/virtualenv/rrb_mnc/3.6/lib/python3.6/site-packages/django/template/backends/django.py", line 84, in reraise
    raise new from exc
django.template.exceptions.TemplateDoesNotExist: header.html
Internal Server Error: /
Traceback (most recent call last):
  File "/home/biommcwj/virtualenv/rrb_mnc/3.6/lib/python3.6/site-packages/django/template/backends/django.py", line 61, in render
    return self.template.render(context)
  File "/home/biommcwj/virtualenv/rrb_mnc/3.6/lib/python3.6/site-packages/django/template/base.py", line 170, in render
    return self._render(context)
  File "/home/biommcwj/virtualenv/rrb_mnc/3.6/lib/python3.6/site-packages/django/template/base.py", line 162, in _render
    return self.nodelist.render(context)
  File "/home/biommcwj/virtualenv/rrb_mnc/3.6/lib/python3.6/site-packages/django/template/base.py", line 938, in render
    bit = node.render_annotated(context)
  File "/home/biommcwj/virtualenv/rrb_mnc/3.6/lib/python3.6/site-packages/django/template/base.py", line 905, in render_annotated
    return self.render(context)
  File "/home/biommcwj/virtualenv/rrb_mnc/3.6/lib/python3.6/site-packages/django/template/loader_tags.py", line 183, in render
    template = context.template.engine.select_template(template_name)
  File "/home/biommcwj/virtualenv/rrb_mnc/3.6/lib/python3.6/site-packages/django/template/engine.py", line 180, in select_template
    raise TemplateDoesNotExist(', '.join(not_found))
django.template.exceptions.TemplateDoesNotExist: header.html

The above exception was the direct cause of the following exception:

Traceback (most recent call last):
  File "/home/biommcwj/virtualenv/rrb_mnc/3.6/lib/python3.6/site-packages/django/core/handlers/exception.py", line 47, in inner
    response = get_response(request)
  File "/home/biommcwj/virtualenv/rrb_mnc/3.6/lib/python3.6/site-packages/django/core/handlers/base.py", line 181, in _get_response
    response = wrapped_callback(request, *callback_args, **callback_kwargs)
  File "/home/biommcwj/rrb_mnc/main/views.py", line 12, in home
    return render(request, 'main/index.html', context)
  File "/home/biommcwj/virtualenv/rrb_mnc/3.6/lib/python3.6/site-packages/django/shortcuts.py", line 19, in render
    content = loader.render_to_string(template_name, context, request, using=using)
  File "/home/biommcwj/virtualenv/rrb_mnc/3.6/lib/python3.6/site-packages/django/template/loader.py", line 62, in render_to_string
    return template.render(context, request)
  File "/home/biommcwj/virtualenv/rrb_mnc/3.6/lib/python3.6/site-packages/django/template/backends/django.py", line 63, in render
    reraise(exc, self.backend)
  File "/home/biommcwj/virtualenv/rrb_mnc/3.6/lib/python3.6/site-packages/django/template/backends/django.py", line 84, in reraise
    raise new from exc
django.template.exceptions.TemplateDoesNotExist: header.html
Internal Server Error: /
Traceback (most recent call last):
  File "/home/biommcwj/virtualenv/rrb_mnc/3.6/lib/python3.6/site-packages/django/template/backends/django.py", line 61, in render
    return self.template.render(context)
  File "/home/biommcwj/virtualenv/rrb_mnc/3.6/lib/python3.6/site-packages/django/template/base.py", line 170, in render
    return self._render(context)
  File "/home/biommcwj/virtualenv/rrb_mnc/3.6/lib/python3.6/site-packages/django/template/base.py", line 162, in _render
    return self.nodelist.render(context)
  File "/home/biommcwj/virtualenv/rrb_mnc/3.6/lib/python3.6/site-packages/django/template/base.py", line 938, in render
    bit = node.render_annotated(context)
  File "/home/biommcwj/virtualenv/rrb_mnc/3.6/lib/python3.6/site-packages/django/template/base.py", line 905, in render_annotated
    return self.render(context)
  File "/home/biommcwj/virtualenv/rrb_mnc/3.6/lib/python3.6/site-packages/django/template/loader_tags.py", line 183, in render
    template = context.template.engine.select_template(template_name)
  File "/home/biommcwj/virtualenv/rrb_mnc/3.6/lib/python3.6/site-packages/django/template/engine.py", line 180, in select_template
    raise TemplateDoesNotExist(', '.join(not_found))
django.template.exceptions.TemplateDoesNotExist: header.html

The above exception was the direct cause of the following exception:

Traceback (most recent call last):
  File "/home/biommcwj/virtualenv/rrb_mnc/3.6/lib/python3.6/site-packages/django/core/handlers/exception.py", line 47, in inner
    response = get_response(request)
  File "/home/biommcwj/virtualenv/rrb_mnc/3.6/lib/python3.6/site-packages/django/core/handlers/base.py", line 181, in _get_response
    response = wrapped_callback(request, *callback_args, **callback_kwargs)
  File "/home/biommcwj/rrb_mnc/main/views.py", line 12, in home
    return render(request, 'main/index.html', context)
  File "/home/biommcwj/virtualenv/rrb_mnc/3.6/lib/python3.6/site-packages/django/shortcuts.py", line 19, in render
    content = loader.render_to_string(template_name, context, request, using=using)
  File "/home/biommcwj/virtualenv/rrb_mnc/3.6/lib/python3.6/site-packages/django/template/loader.py", line 62, in render_to_string
    return template.render(context, request)
  File "/home/biommcwj/virtualenv/rrb_mnc/3.6/lib/python3.6/site-packages/django/template/backends/django.py", line 63, in render
    reraise(exc, self.backend)
  File "/home/biommcwj/virtualenv/rrb_mnc/3.6/lib/python3.6/site-packages/django/template/backends/django.py", line 84, in reraise
    raise new from exc
django.template.exceptions.TemplateDoesNotExist: header.html
Traceback (most recent call last):
  File "/home/biommcwj/rrb_mnc/passenger_wsgi.py", line 1, in <module>
    from images.wsgi import  application
  File "/home/biommcwj/rrb_mnc/images/wsgi.py", line 16, in <module>
    application = get_wsgi_application()
  File "/home/biommcwj/virtualenv/rrb_mnc/3.6/lib/python3.6/site-packages/django/core/wsgi.py", line 12, in get_wsgi_application
    django.setup(set_prefix=False)
  File "/home/biommcwj/virtualenv/rrb_mnc/3.6/lib/python3.6/site-packages/django/__init__.py", line 19, in setup
    configure_logging(settings.LOGGING_CONFIG, settings.LOGGING)
  File "/home/biommcwj/virtualenv/rrb_mnc/3.6/lib/python3.6/site-packages/django/conf/__init__.py", line 82, in __getattr__
    self._setup(name)
  File "/home/biommcwj/virtualenv/rrb_mnc/3.6/lib/python3.6/site-packages/django/conf/__init__.py", line 69, in _setup
    self._wrapped = Settings(settings_module)
  File "/home/biommcwj/virtualenv/rrb_mnc/3.6/lib/python3.6/site-packages/django/conf/__init__.py", line 170, in __init__
    mod = importlib.import_module(self.SETTINGS_MODULE)
  File "/opt/alt/python36/lib64/python3.6/importlib/__init__.py", line 126, in import_module
    return _bootstrap._gcd_import(name[level:], package, level)
  File "/home/biommcwj/rrb_mnc/images/settings.py", line 59, in <module>
    'DIRS': [BASE_DIR / "templates"],
TypeError: unsupported operand type(s) for /: 'str' and 'str'
Traceback (most recent call last):
  File "/home/biommcwj/rrb_mnc/passenger_wsgi.py", line 1, in <module>
    from images.wsgi import  application
  File "/home/biommcwj/rrb_mnc/images/wsgi.py", line 16, in <module>
    application = get_wsgi_application()
  File "/home/biommcwj/virtualenv/rrb_mnc/3.6/lib/python3.6/site-packages/django/core/wsgi.py", line 12, in get_wsgi_application
    django.setup(set_prefix=False)
  File "/home/biommcwj/virtualenv/rrb_mnc/3.6/lib/python3.6/site-packages/django/__init__.py", line 19, in setup
    configure_logging(settings.LOGGING_CONFIG, settings.LOGGING)
  File "/home/biommcwj/virtualenv/rrb_mnc/3.6/lib/python3.6/site-packages/django/conf/__init__.py", line 82, in __getattr__
    self._setup(name)
  File "/home/biommcwj/virtualenv/rrb_mnc/3.6/lib/python3.6/site-packages/django/conf/__init__.py", line 69, in _setup
    self._wrapped = Settings(settings_module)
  File "/home/biommcwj/virtualenv/rrb_mnc/3.6/lib/python3.6/site-packages/django/conf/__init__.py", line 170, in __init__
    mod = importlib.import_module(self.SETTINGS_MODULE)
  File "/opt/alt/python36/lib64/python3.6/importlib/__init__.py", line 126, in import_module
    return _bootstrap._gcd_import(name[level:], package, level)
  File "/home/biommcwj/rrb_mnc/images/settings.py", line 59, in <module>
    'DIRS': [BASE_DIR / "templates"],
TypeError: unsupported operand type(s) for /: 'str' and 'str'
Internal Server Error: /
Traceback (most recent call last):
  File "/home/biommcwj/virtualenv/rrb_mnc/3.6/lib/python3.6/site-packages/django/template/backends/django.py", line 61, in render
    return self.template.render(context)
  File "/home/biommcwj/virtualenv/rrb_mnc/3.6/lib/python3.6/site-packages/django/template/base.py", line 170, in render
    return self._render(context)
  File "/home/biommcwj/virtualenv/rrb_mnc/3.6/lib/python3.6/site-packages/django/template/base.py", line 162, in _render
    return self.nodelist.render(context)
  File "/home/biommcwj/virtualenv/rrb_mnc/3.6/lib/python3.6/site-packages/django/template/base.py", line 938, in render
    bit = node.render_annotated(context)
  File "/home/biommcwj/virtualenv/rrb_mnc/3.6/lib/python3.6/site-packages/django/template/base.py", line 905, in render_annotated
    return self.render(context)
  File "/home/biommcwj/virtualenv/rrb_mnc/3.6/lib/python3.6/site-packages/django/template/loader_tags.py", line 183, in render
    template = context.template.engine.select_template(template_name)
  File "/home/biommcwj/virtualenv/rrb_mnc/3.6/lib/python3.6/site-packages/django/template/engine.py", line 180, in select_template
    raise TemplateDoesNotExist(', '.join(not_found))
django.template.exceptions.TemplateDoesNotExist: header.html

The above exception was the direct cause of the following exception:

Traceback (most recent call last):
  File "/home/biommcwj/virtualenv/rrb_mnc/3.6/lib/python3.6/site-packages/django/core/handlers/exception.py", line 47, in inner
    response = get_response(request)
  File "/home/biommcwj/virtualenv/rrb_mnc/3.6/lib/python3.6/site-packages/django/core/handlers/base.py", line 181, in _get_response
    response = wrapped_callback(request, *callback_args, **callback_kwargs)
  File "/home/biommcwj/rrb_mnc/main/views.py", line 12, in home
    return render(request, 'main/index.html', context)
  File "/home/biommcwj/virtualenv/rrb_mnc/3.6/lib/python3.6/site-packages/django/shortcuts.py", line 19, in render
    content = loader.render_to_string(template_name, context, request, using=using)
  File "/home/biommcwj/virtualenv/rrb_mnc/3.6/lib/python3.6/site-packages/django/template/loader.py", line 62, in render_to_string
    return template.render(context, request)
  File "/home/biommcwj/virtualenv/rrb_mnc/3.6/lib/python3.6/site-packages/django/template/backends/django.py", line 63, in render
    reraise(exc, self.backend)
  File "/home/biommcwj/virtualenv/rrb_mnc/3.6/lib/python3.6/site-packages/django/template/backends/django.py", line 84, in reraise
    raise new from exc
django.template.exceptions.TemplateDoesNotExist: header.html
Internal Server Error: /
Traceback (most recent call last):
  File "/home/biommcwj/virtualenv/rrb_mnc/3.6/lib/python3.6/site-packages/django/template/backends/django.py", line 61, in render
    return self.template.render(context)
  File "/home/biommcwj/virtualenv/rrb_mnc/3.6/lib/python3.6/site-packages/django/template/base.py", line 170, in render
    return self._render(context)
  File "/home/biommcwj/virtualenv/rrb_mnc/3.6/lib/python3.6/site-packages/django/template/base.py", line 162, in _render
    return self.nodelist.render(context)
  File "/home/biommcwj/virtualenv/rrb_mnc/3.6/lib/python3.6/site-packages/django/template/base.py", line 938, in render
    bit = node.render_annotated(context)
  File "/home/biommcwj/virtualenv/rrb_mnc/3.6/lib/python3.6/site-packages/django/template/base.py", line 905, in render_annotated
    return self.render(context)
  File "/home/biommcwj/virtualenv/rrb_mnc/3.6/lib/python3.6/site-packages/django/template/loader_tags.py", line 183, in render
    template = context.template.engine.select_template(template_name)
  File "/home/biommcwj/virtualenv/rrb_mnc/3.6/lib/python3.6/site-packages/django/template/engine.py", line 180, in select_template
    raise TemplateDoesNotExist(', '.join(not_found))
django.template.exceptions.TemplateDoesNotExist: header.html

The above exception was the direct cause of the following exception:

Traceback (most recent call last):
  File "/home/biommcwj/virtualenv/rrb_mnc/3.6/lib/python3.6/site-packages/django/core/handlers/exception.py", line 47, in inner
    response = get_response(request)
  File "/home/biommcwj/virtualenv/rrb_mnc/3.6/lib/python3.6/site-packages/django/core/handlers/base.py", line 181, in _get_response
    response = wrapped_callback(request, *callback_args, **callback_kwargs)
  File "/home/biommcwj/rrb_mnc/main/views.py", line 12, in home
    return render(request, 'main/index.html', context)
  File "/home/biommcwj/virtualenv/rrb_mnc/3.6/lib/python3.6/site-packages/django/shortcuts.py", line 19, in render
    content = loader.render_to_string(template_name, context, request, using=using)
  File "/home/biommcwj/virtualenv/rrb_mnc/3.6/lib/python3.6/site-packages/django/template/loader.py", line 62, in render_to_string
    return template.render(context, request)
  File "/home/biommcwj/virtualenv/rrb_mnc/3.6/lib/python3.6/site-packages/django/template/backends/django.py", line 63, in render
    reraise(exc, self.backend)
  File "/home/biommcwj/virtualenv/rrb_mnc/3.6/lib/python3.6/site-packages/django/template/backends/django.py", line 84, in reraise
    raise new from exc
django.template.exceptions.TemplateDoesNotExist: header.html
Internal Server Error: /
Traceback (most recent call last):
  File "/home/biommcwj/virtualenv/rrb_mnc/3.6/lib/python3.6/site-packages/django/template/backends/django.py", line 61, in render
    return self.template.render(context)
  File "/home/biommcwj/virtualenv/rrb_mnc/3.6/lib/python3.6/site-packages/django/template/base.py", line 170, in render
    return self._render(context)
  File "/home/biommcwj/virtualenv/rrb_mnc/3.6/lib/python3.6/site-packages/django/template/base.py", line 162, in _render
    return self.nodelist.render(context)
  File "/home/biommcwj/virtualenv/rrb_mnc/3.6/lib/python3.6/site-packages/django/template/base.py", line 938, in render
    bit = node.render_annotated(context)
  File "/home/biommcwj/virtualenv/rrb_mnc/3.6/lib/python3.6/site-packages/django/template/base.py", line 905, in render_annotated
    return self.render(context)
  File "/home/biommcwj/virtualenv/rrb_mnc/3.6/lib/python3.6/site-packages/django/template/loader_tags.py", line 183, in render
    template = context.template.engine.select_template(template_name)
  File "/home/biommcwj/virtualenv/rrb_mnc/3.6/lib/python3.6/site-packages/django/template/engine.py", line 180, in select_template
    raise TemplateDoesNotExist(', '.join(not_found))
django.template.exceptions.TemplateDoesNotExist: header.html

The above exception was the direct cause of the following exception:

Traceback (most recent call last):
  File "/home/biommcwj/virtualenv/rrb_mnc/3.6/lib/python3.6/site-packages/django/core/handlers/exception.py", line 47, in inner
    response = get_response(request)
  File "/home/biommcwj/virtualenv/rrb_mnc/3.6/lib/python3.6/site-packages/django/core/handlers/base.py", line 181, in _get_response
    response = wrapped_callback(request, *callback_args, **callback_kwargs)
  File "/home/biommcwj/rrb_mnc/main/views.py", line 12, in home
    return render(request, 'main/index.html', context)
  File "/home/biommcwj/virtualenv/rrb_mnc/3.6/lib/python3.6/site-packages/django/shortcuts.py", line 19, in render
    content = loader.render_to_string(template_name, context, request, using=using)
  File "/home/biommcwj/virtualenv/rrb_mnc/3.6/lib/python3.6/site-packages/django/template/loader.py", line 62, in render_to_string
    return template.render(context, request)
  File "/home/biommcwj/virtualenv/rrb_mnc/3.6/lib/python3.6/site-packages/django/template/backends/django.py", line 63, in render
    reraise(exc, self.backend)
  File "/home/biommcwj/virtualenv/rrb_mnc/3.6/lib/python3.6/site-packages/django/template/backends/django.py", line 84, in reraise
    raise new from exc
django.template.exceptions.TemplateDoesNotExist: header.html
Internal Server Error: /
Traceback (most recent call last):
  File "/home/biommcwj/virtualenv/rrb_mnc/3.6/lib/python3.6/site-packages/django/template/backends/django.py", line 61, in render
    return self.template.render(context)
  File "/home/biommcwj/virtualenv/rrb_mnc/3.6/lib/python3.6/site-packages/django/template/base.py", line 170, in render
    return self._render(context)
  File "/home/biommcwj/virtualenv/rrb_mnc/3.6/lib/python3.6/site-packages/django/template/base.py", line 162, in _render
    return self.nodelist.render(context)
  File "/home/biommcwj/virtualenv/rrb_mnc/3.6/lib/python3.6/site-packages/django/template/base.py", line 938, in render
    bit = node.render_annotated(context)
  File "/home/biommcwj/virtualenv/rrb_mnc/3.6/lib/python3.6/site-packages/django/template/base.py", line 905, in render_annotated
    return self.render(context)
  File "/home/biommcwj/virtualenv/rrb_mnc/3.6/lib/python3.6/site-packages/django/template/loader_tags.py", line 183, in render
    template = context.template.engine.select_template(template_name)
  File "/home/biommcwj/virtualenv/rrb_mnc/3.6/lib/python3.6/site-packages/django/template/engine.py", line 180, in select_template
    raise TemplateDoesNotExist(', '.join(not_found))
django.template.exceptions.TemplateDoesNotExist: header.html

The above exception was the direct cause of the following exception:

Traceback (most recent call last):
  File "/home/biommcwj/virtualenv/rrb_mnc/3.6/lib/python3.6/site-packages/django/core/handlers/exception.py", line 47, in inner
    response = get_response(request)
  File "/home/biommcwj/virtualenv/rrb_mnc/3.6/lib/python3.6/site-packages/django/core/handlers/base.py", line 181, in _get_response
    response = wrapped_callback(request, *callback_args, **callback_kwargs)
  File "/home/biommcwj/rrb_mnc/main/views.py", line 12, in home
    return render(request, 'main/index.html', context)
  File "/home/biommcwj/virtualenv/rrb_mnc/3.6/lib/python3.6/site-packages/django/shortcuts.py", line 19, in render
    content = loader.render_to_string(template_name, context, request, using=using)
  File "/home/biommcwj/virtualenv/rrb_mnc/3.6/lib/python3.6/site-packages/django/template/loader.py", line 62, in render_to_string
    return template.render(context, request)
  File "/home/biommcwj/virtualenv/rrb_mnc/3.6/lib/python3.6/site-packages/django/template/backends/django.py", line 63, in render
    reraise(exc, self.backend)
  File "/home/biommcwj/virtualenv/rrb_mnc/3.6/lib/python3.6/site-packages/django/template/backends/django.py", line 84, in reraise
    raise new from exc
django.template.exceptions.TemplateDoesNotExist: header.html
Traceback (most recent call last):
  File "/home/biommcwj/rrb_mnc/passenger_wsgi.py", line 1, in <module>
    from images.wsgi import  application
  File "/home/biommcwj/rrb_mnc/images/wsgi.py", line 16, in <module>
    application = get_wsgi_application()
  File "/home/biommcwj/virtualenv/rrb_mnc/3.6/lib/python3.6/site-packages/django/core/wsgi.py", line 12, in get_wsgi_application
    django.setup(set_prefix=False)
  File "/home/biommcwj/virtualenv/rrb_mnc/3.6/lib/python3.6/site-packages/django/__init__.py", line 19, in setup
    configure_logging(settings.LOGGING_CONFIG, settings.LOGGING)
  File "/home/biommcwj/virtualenv/rrb_mnc/3.6/lib/python3.6/site-packages/django/conf/__init__.py", line 82, in __getattr__
    self._setup(name)
  File "/home/biommcwj/virtualenv/rrb_mnc/3.6/lib/python3.6/site-packages/django/conf/__init__.py", line 69, in _setup
    self._wrapped = Settings(settings_module)
  File "/home/biommcwj/virtualenv/rrb_mnc/3.6/lib/python3.6/site-packages/django/conf/__init__.py", line 170, in __init__
    mod = importlib.import_module(self.SETTINGS_MODULE)
  File "/opt/alt/python36/lib64/python3.6/importlib/__init__.py", line 126, in import_module
    return _bootstrap._gcd_import(name[level:], package, level)
  File "/home/biommcwj/rrb_mnc/images/settings.py", line 59, in <module>
    'DIRS': [BASE_DIR / "templates"],
TypeError: unsupported operand type(s) for /: 'str' and 'str'
Not Found: /favicon.ico
Not Found: /favicon.ico
Not Found: /favicon.ico
Not Found: /favicon.ico
Internal Server Error: /admin/main/image/add/
Traceback (most recent call last):
  File "/home/biommcwj/virtualenv/rrb_mnc/3.6/lib/python3.6/site-packages/django/db/backends/utils.py", line 84, in _execute
    return self.cursor.execute(sql, params)
  File "/home/biommcwj/virtualenv/rrb_mnc/3.6/lib/python3.6/site-packages/django/db/backends/mysql/base.py", line 73, in execute
    return self.cursor.execute(query, args)
  File "/home/biommcwj/virtualenv/rrb_mnc/3.6/lib64/python3.6/site-packages/MySQLdb/cursors.py", line 206, in execute
    res = self._query(query)
  File "/home/biommcwj/virtualenv/rrb_mnc/3.6/lib64/python3.6/site-packages/MySQLdb/cursors.py", line 319, in _query
    db.query(q)
  File "/home/biommcwj/virtualenv/rrb_mnc/3.6/lib64/python3.6/site-packages/MySQLdb/connections.py", line 254, in query
    _mysql.connection.query(self, query)
MySQLdb._exceptions.IntegrityError: (1062, "Duplicate entry 'dhalai' for key 'slug'")

The above exception was the direct cause of the following exception:

Traceback (most recent call last):
  File "/home/biommcwj/virtualenv/rrb_mnc/3.6/lib/python3.6/site-packages/django/core/handlers/exception.py", line 47, in inner
    response = get_response(request)
  File "/home/biommcwj/virtualenv/rrb_mnc/3.6/lib/python3.6/site-packages/django/core/handlers/base.py", line 181, in _get_response
    response = wrapped_callback(request, *callback_args, **callback_kwargs)
  File "/home/biommcwj/virtualenv/rrb_mnc/3.6/lib/python3.6/site-packages/django/contrib/admin/options.py", line 616, in wrapper
    return self.admin_site.admin_view(view)(*args, **kwargs)
  File "/home/biommcwj/virtualenv/rrb_mnc/3.6/lib/python3.6/site-packages/django/utils/decorators.py", line 130, in _wrapped_view
    response = view_func(request, *args, **kwargs)
  File "/home/biommcwj/virtualenv/rrb_mnc/3.6/lib/python3.6/site-packages/django/views/decorators/cache.py", line 44, in _wrapped_view_func
    response = view_func(request, *args, **kwargs)
  File "/home/biommcwj/virtualenv/rrb_mnc/3.6/lib/python3.6/site-packages/django/contrib/admin/sites.py", line 232, in inner
    return view(request, *args, **kwargs)
  File "/home/biommcwj/virtualenv/rrb_mnc/3.6/lib/python3.6/site-packages/django/contrib/admin/options.py", line 1657, in add_view
    return self.changeform_view(request, None, form_url, extra_context)
  File "/home/biommcwj/virtualenv/rrb_mnc/3.6/lib/python3.6/site-packages/django/utils/decorators.py", line 43, in _wrapper
    return bound_method(*args, **kwargs)
  File "/home/biommcwj/virtualenv/rrb_mnc/3.6/lib/python3.6/site-packages/django/utils/decorators.py", line 130, in _wrapped_view
    response = view_func(request, *args, **kwargs)
  File "/home/biommcwj/virtualenv/rrb_mnc/3.6/lib/python3.6/site-packages/django/contrib/admin/options.py", line 1540, in changeform_view
    return self._changeform_view(request, object_id, form_url, extra_context)
  File "/home/biommcwj/virtualenv/rrb_mnc/3.6/lib/python3.6/site-packages/django/contrib/admin/options.py", line 1586, in _changeform_view
    self.save_model(request, new_object, form, not add)
  File "/home/biommcwj/virtualenv/rrb_mnc/3.6/lib/python3.6/site-packages/django/contrib/admin/options.py", line 1099, in save_model
    obj.save()
  File "/home/biommcwj/rrb_mnc/main/models.py", line 79, in save
    super(Image, self).save(*args, **kwargs)
  File "/home/biommcwj/virtualenv/rrb_mnc/3.6/lib/python3.6/site-packages/django/db/models/base.py", line 727, in save
    force_update=force_update, update_fields=update_fields)
  File "/home/biommcwj/virtualenv/rrb_mnc/3.6/lib/python3.6/site-packages/django/db/models/base.py", line 765, in save_base
    force_update, using, update_fields,
  File "/home/biommcwj/virtualenv/rrb_mnc/3.6/lib/python3.6/site-packages/django/db/models/base.py", line 868, in _save_table
    results = self._do_insert(cls._base_manager, using, fields, returning_fields, raw)
  File "/home/biommcwj/virtualenv/rrb_mnc/3.6/lib/python3.6/site-packages/django/db/models/base.py", line 908, in _do_insert
    using=using, raw=raw,
  File "/home/biommcwj/virtualenv/rrb_mnc/3.6/lib/python3.6/site-packages/django/db/models/manager.py", line 85, in manager_method
    return getattr(self.get_queryset(), name)(*args, **kwargs)
  File "/home/biommcwj/virtualenv/rrb_mnc/3.6/lib/python3.6/site-packages/django/db/models/query.py", line 1270, in _insert
    return query.get_compiler(using=using).execute_sql(returning_fields)
  File "/home/biommcwj/virtualenv/rrb_mnc/3.6/lib/python3.6/site-packages/django/db/models/sql/compiler.py", line 1416, in execute_sql
    cursor.execute(sql, params)
  File "/home/biommcwj/virtualenv/rrb_mnc/3.6/lib/python3.6/site-packages/django/db/backends/utils.py", line 98, in execute
    return super().execute(sql, params)
  File "/home/biommcwj/virtualenv/rrb_mnc/3.6/lib/python3.6/site-packages/django/db/backends/utils.py", line 66, in execute
    return self._execute_with_wrappers(sql, params, many=False, executor=self._execute)
  File "/home/biommcwj/virtualenv/rrb_mnc/3.6/lib/python3.6/site-packages/django/db/backends/utils.py", line 75, in _execute_with_wrappers
    return executor(sql, params, many, context)
  File "/home/biommcwj/virtualenv/rrb_mnc/3.6/lib/python3.6/site-packages/django/db/backends/utils.py", line 84, in _execute
    return self.cursor.execute(sql, params)
  File "/home/biommcwj/virtualenv/rrb_mnc/3.6/lib/python3.6/site-packages/django/db/utils.py", line 90, in __exit__
    raise dj_exc_value.with_traceback(traceback) from exc_value
  File "/home/biommcwj/virtualenv/rrb_mnc/3.6/lib/python3.6/site-packages/django/db/backends/utils.py", line 84, in _execute
    return self.cursor.execute(sql, params)
  File "/home/biommcwj/virtualenv/rrb_mnc/3.6/lib/python3.6/site-packages/django/db/backends/mysql/base.py", line 73, in execute
    return self.cursor.execute(query, args)
  File "/home/biommcwj/virtualenv/rrb_mnc/3.6/lib64/python3.6/site-packages/MySQLdb/cursors.py", line 206, in execute
    res = self._query(query)
  File "/home/biommcwj/virtualenv/rrb_mnc/3.6/lib64/python3.6/site-packages/MySQLdb/cursors.py", line 319, in _query
    db.query(q)
  File "/home/biommcwj/virtualenv/rrb_mnc/3.6/lib64/python3.6/site-packages/MySQLdb/connections.py", line 254, in query
    _mysql.connection.query(self, query)
django.db.utils.IntegrityError: (1062, "Duplicate entry 'dhalai' for key 'slug'")
Internal Server Error: /admin/main/image/add/
Traceback (most recent call last):
  File "/home/biommcwj/virtualenv/rrb_mnc/3.6/lib/python3.6/site-packages/django/db/backends/utils.py", line 84, in _execute
    return self.cursor.execute(sql, params)
  File "/home/biommcwj/virtualenv/rrb_mnc/3.6/lib/python3.6/site-packages/django/db/backends/mysql/base.py", line 73, in execute
    return self.cursor.execute(query, args)
  File "/home/biommcwj/virtualenv/rrb_mnc/3.6/lib64/python3.6/site-packages/MySQLdb/cursors.py", line 206, in execute
    res = self._query(query)
  File "/home/biommcwj/virtualenv/rrb_mnc/3.6/lib64/python3.6/site-packages/MySQLdb/cursors.py", line 319, in _query
    db.query(q)
  File "/home/biommcwj/virtualenv/rrb_mnc/3.6/lib64/python3.6/site-packages/MySQLdb/connections.py", line 254, in query
    _mysql.connection.query(self, query)
MySQLdb._exceptions.IntegrityError: (1062, "Duplicate entry 'dhalai' for key 'slug'")

The above exception was the direct cause of the following exception:

Traceback (most recent call last):
  File "/home/biommcwj/virtualenv/rrb_mnc/3.6/lib/python3.6/site-packages/django/core/handlers/exception.py", line 47, in inner
    response = get_response(request)
  File "/home/biommcwj/virtualenv/rrb_mnc/3.6/lib/python3.6/site-packages/django/core/handlers/base.py", line 181, in _get_response
    response = wrapped_callback(request, *callback_args, **callback_kwargs)
  File "/home/biommcwj/virtualenv/rrb_mnc/3.6/lib/python3.6/site-packages/django/contrib/admin/options.py", line 616, in wrapper
    return self.admin_site.admin_view(view)(*args, **kwargs)
  File "/home/biommcwj/virtualenv/rrb_mnc/3.6/lib/python3.6/site-packages/django/utils/decorators.py", line 130, in _wrapped_view
    response = view_func(request, *args, **kwargs)
  File "/home/biommcwj/virtualenv/rrb_mnc/3.6/lib/python3.6/site-packages/django/views/decorators/cache.py", line 44, in _wrapped_view_func
    response = view_func(request, *args, **kwargs)
  File "/home/biommcwj/virtualenv/rrb_mnc/3.6/lib/python3.6/site-packages/django/contrib/admin/sites.py", line 232, in inner
    return view(request, *args, **kwargs)
  File "/home/biommcwj/virtualenv/rrb_mnc/3.6/lib/python3.6/site-packages/django/contrib/admin/options.py", line 1657, in add_view
    return self.changeform_view(request, None, form_url, extra_context)
  File "/home/biommcwj/virtualenv/rrb_mnc/3.6/lib/python3.6/site-packages/django/utils/decorators.py", line 43, in _wrapper
    return bound_method(*args, **kwargs)
  File "/home/biommcwj/virtualenv/rrb_mnc/3.6/lib/python3.6/site-packages/django/utils/decorators.py", line 130, in _wrapped_view
    response = view_func(request, *args, **kwargs)
  File "/home/biommcwj/virtualenv/rrb_mnc/3.6/lib/python3.6/site-packages/django/contrib/admin/options.py", line 1540, in changeform_view
    return self._changeform_view(request, object_id, form_url, extra_context)
  File "/home/biommcwj/virtualenv/rrb_mnc/3.6/lib/python3.6/site-packages/django/contrib/admin/options.py", line 1586, in _changeform_view
    self.save_model(request, new_object, form, not add)
  File "/home/biommcwj/virtualenv/rrb_mnc/3.6/lib/python3.6/site-packages/django/contrib/admin/options.py", line 1099, in save_model
    obj.save()
  File "/home/biommcwj/rrb_mnc/main/models.py", line 79, in save
    super(Image, self).save(*args, **kwargs)
  File "/home/biommcwj/virtualenv/rrb_mnc/3.6/lib/python3.6/site-packages/django/db/models/base.py", line 727, in save
    force_update=force_update, update_fields=update_fields)
  File "/home/biommcwj/virtualenv/rrb_mnc/3.6/lib/python3.6/site-packages/django/db/models/base.py", line 765, in save_base
    force_update, using, update_fields,
  File "/home/biommcwj/virtualenv/rrb_mnc/3.6/lib/python3.6/site-packages/django/db/models/base.py", line 868, in _save_table
    results = self._do_insert(cls._base_manager, using, fields, returning_fields, raw)
  File "/home/biommcwj/virtualenv/rrb_mnc/3.6/lib/python3.6/site-packages/django/db/models/base.py", line 908, in _do_insert
    using=using, raw=raw,
  File "/home/biommcwj/virtualenv/rrb_mnc/3.6/lib/python3.6/site-packages/django/db/models/manager.py", line 85, in manager_method
    return getattr(self.get_queryset(), name)(*args, **kwargs)
  File "/home/biommcwj/virtualenv/rrb_mnc/3.6/lib/python3.6/site-packages/django/db/models/query.py", line 1270, in _insert
    return query.get_compiler(using=using).execute_sql(returning_fields)
  File "/home/biommcwj/virtualenv/rrb_mnc/3.6/lib/python3.6/site-packages/django/db/models/sql/compiler.py", line 1416, in execute_sql
    cursor.execute(sql, params)
  File "/home/biommcwj/virtualenv/rrb_mnc/3.6/lib/python3.6/site-packages/django/db/backends/utils.py", line 98, in execute
    return super().execute(sql, params)
  File "/home/biommcwj/virtualenv/rrb_mnc/3.6/lib/python3.6/site-packages/django/db/backends/utils.py", line 66, in execute
    return self._execute_with_wrappers(sql, params, many=False, executor=self._execute)
  File "/home/biommcwj/virtualenv/rrb_mnc/3.6/lib/python3.6/site-packages/django/db/backends/utils.py", line 75, in _execute_with_wrappers
    return executor(sql, params, many, context)
  File "/home/biommcwj/virtualenv/rrb_mnc/3.6/lib/python3.6/site-packages/django/db/backends/utils.py", line 84, in _execute
    return self.cursor.execute(sql, params)
  File "/home/biommcwj/virtualenv/rrb_mnc/3.6/lib/python3.6/site-packages/django/db/utils.py", line 90, in __exit__
    raise dj_exc_value.with_traceback(traceback) from exc_value
  File "/home/biommcwj/virtualenv/rrb_mnc/3.6/lib/python3.6/site-packages/django/db/backends/utils.py", line 84, in _execute
    return self.cursor.execute(sql, params)
  File "/home/biommcwj/virtualenv/rrb_mnc/3.6/lib/python3.6/site-packages/django/db/backends/mysql/base.py", line 73, in execute
    return self.cursor.execute(query, args)
  File "/home/biommcwj/virtualenv/rrb_mnc/3.6/lib64/python3.6/site-packages/MySQLdb/cursors.py", line 206, in execute
    res = self._query(query)
  File "/home/biommcwj/virtualenv/rrb_mnc/3.6/lib64/python3.6/site-packages/MySQLdb/cursors.py", line 319, in _query
    db.query(q)
  File "/home/biommcwj/virtualenv/rrb_mnc/3.6/lib64/python3.6/site-packages/MySQLdb/connections.py", line 254, in query
    _mysql.connection.query(self, query)
django.db.utils.IntegrityError: (1062, "Duplicate entry 'dhalai' for key 'slug'")
Internal Server Error: /admin/main/image/add/
Traceback (most recent call last):
  File "/home/biommcwj/virtualenv/rrb_mnc/3.6/lib/python3.6/site-packages/django/db/backends/utils.py", line 84, in _execute
    return self.cursor.execute(sql, params)
  File "/home/biommcwj/virtualenv/rrb_mnc/3.6/lib/python3.6/site-packages/django/db/backends/mysql/base.py", line 73, in execute
    return self.cursor.execute(query, args)
  File "/home/biommcwj/virtualenv/rrb_mnc/3.6/lib64/python3.6/site-packages/MySQLdb/cursors.py", line 206, in execute
    res = self._query(query)
  File "/home/biommcwj/virtualenv/rrb_mnc/3.6/lib64/python3.6/site-packages/MySQLdb/cursors.py", line 319, in _query
    db.query(q)
  File "/home/biommcwj/virtualenv/rrb_mnc/3.6/lib64/python3.6/site-packages/MySQLdb/connections.py", line 254, in query
    _mysql.connection.query(self, query)
MySQLdb._exceptions.IntegrityError: (1062, "Duplicate entry 'dhalai' for key 'slug'")

The above exception was the direct cause of the following exception:

Traceback (most recent call last):
  File "/home/biommcwj/virtualenv/rrb_mnc/3.6/lib/python3.6/site-packages/django/core/handlers/exception.py", line 47, in inner
    response = get_response(request)
  File "/home/biommcwj/virtualenv/rrb_mnc/3.6/lib/python3.6/site-packages/django/core/handlers/base.py", line 181, in _get_response
    response = wrapped_callback(request, *callback_args, **callback_kwargs)
  File "/home/biommcwj/virtualenv/rrb_mnc/3.6/lib/python3.6/site-packages/django/contrib/admin/options.py", line 616, in wrapper
    return self.admin_site.admin_view(view)(*args, **kwargs)
  File "/home/biommcwj/virtualenv/rrb_mnc/3.6/lib/python3.6/site-packages/django/utils/decorators.py", line 130, in _wrapped_view
    response = view_func(request, *args, **kwargs)
  File "/home/biommcwj/virtualenv/rrb_mnc/3.6/lib/python3.6/site-packages/django/views/decorators/cache.py", line 44, in _wrapped_view_func
    response = view_func(request, *args, **kwargs)
  File "/home/biommcwj/virtualenv/rrb_mnc/3.6/lib/python3.6/site-packages/django/contrib/admin/sites.py", line 232, in inner
    return view(request, *args, **kwargs)
  File "/home/biommcwj/virtualenv/rrb_mnc/3.6/lib/python3.6/site-packages/django/contrib/admin/options.py", line 1657, in add_view
    return self.changeform_view(request, None, form_url, extra_context)
  File "/home/biommcwj/virtualenv/rrb_mnc/3.6/lib/python3.6/site-packages/django/utils/decorators.py", line 43, in _wrapper
    return bound_method(*args, **kwargs)
  File "/home/biommcwj/virtualenv/rrb_mnc/3.6/lib/python3.6/site-packages/django/utils/decorators.py", line 130, in _wrapped_view
    response = view_func(request, *args, **kwargs)
  File "/home/biommcwj/virtualenv/rrb_mnc/3.6/lib/python3.6/site-packages/django/contrib/admin/options.py", line 1540, in changeform_view
    return self._changeform_view(request, object_id, form_url, extra_context)
  File "/home/biommcwj/virtualenv/rrb_mnc/3.6/lib/python3.6/site-packages/django/contrib/admin/options.py", line 1586, in _changeform_view
    self.save_model(request, new_object, form, not add)
  File "/home/biommcwj/virtualenv/rrb_mnc/3.6/lib/python3.6/site-packages/django/contrib/admin/options.py", line 1099, in save_model
    obj.save()
  File "/home/biommcwj/rrb_mnc/main/models.py", line 79, in save
    super(Image, self).save(*args, **kwargs)
  File "/home/biommcwj/virtualenv/rrb_mnc/3.6/lib/python3.6/site-packages/django/db/models/base.py", line 727, in save
    force_update=force_update, update_fields=update_fields)
  File "/home/biommcwj/virtualenv/rrb_mnc/3.6/lib/python3.6/site-packages/django/db/models/base.py", line 765, in save_base
    force_update, using, update_fields,
  File "/home/biommcwj/virtualenv/rrb_mnc/3.6/lib/python3.6/site-packages/django/db/models/base.py", line 868, in _save_table
    results = self._do_insert(cls._base_manager, using, fields, returning_fields, raw)
  File "/home/biommcwj/virtualenv/rrb_mnc/3.6/lib/python3.6/site-packages/django/db/models/base.py", line 908, in _do_insert
    using=using, raw=raw,
  File "/home/biommcwj/virtualenv/rrb_mnc/3.6/lib/python3.6/site-packages/django/db/models/manager.py", line 85, in manager_method
    return getattr(self.get_queryset(), name)(*args, **kwargs)
  File "/home/biommcwj/virtualenv/rrb_mnc/3.6/lib/python3.6/site-packages/django/db/models/query.py", line 1270, in _insert
    return query.get_compiler(using=using).execute_sql(returning_fields)
  File "/home/biommcwj/virtualenv/rrb_mnc/3.6/lib/python3.6/site-packages/django/db/models/sql/compiler.py", line 1416, in execute_sql
    cursor.execute(sql, params)
  File "/home/biommcwj/virtualenv/rrb_mnc/3.6/lib/python3.6/site-packages/django/db/backends/utils.py", line 98, in execute
    return super().execute(sql, params)
  File "/home/biommcwj/virtualenv/rrb_mnc/3.6/lib/python3.6/site-packages/django/db/backends/utils.py", line 66, in execute
    return self._execute_with_wrappers(sql, params, many=False, executor=self._execute)
  File "/home/biommcwj/virtualenv/rrb_mnc/3.6/lib/python3.6/site-packages/django/db/backends/utils.py", line 75, in _execute_with_wrappers
    return executor(sql, params, many, context)
  File "/home/biommcwj/virtualenv/rrb_mnc/3.6/lib/python3.6/site-packages/django/db/backends/utils.py", line 84, in _execute
    return self.cursor.execute(sql, params)
  File "/home/biommcwj/virtualenv/rrb_mnc/3.6/lib/python3.6/site-packages/django/db/utils.py", line 90, in __exit__
    raise dj_exc_value.with_traceback(traceback) from exc_value
  File "/home/biommcwj/virtualenv/rrb_mnc/3.6/lib/python3.6/site-packages/django/db/backends/utils.py", line 84, in _execute
    return self.cursor.execute(sql, params)
  File "/home/biommcwj/virtualenv/rrb_mnc/3.6/lib/python3.6/site-packages/django/db/backends/mysql/base.py", line 73, in execute
    return self.cursor.execute(query, args)
  File "/home/biommcwj/virtualenv/rrb_mnc/3.6/lib64/python3.6/site-packages/MySQLdb/cursors.py", line 206, in execute
    res = self._query(query)
  File "/home/biommcwj/virtualenv/rrb_mnc/3.6/lib64/python3.6/site-packages/MySQLdb/cursors.py", line 319, in _query
    db.query(q)
  File "/home/biommcwj/virtualenv/rrb_mnc/3.6/lib64/python3.6/site-packages/MySQLdb/connections.py", line 254, in query
    _mysql.connection.query(self, query)
django.db.utils.IntegrityError: (1062, "Duplicate entry 'dhalai' for key 'slug'")
Internal Server Error: /admin/main/image/add/
Traceback (most recent call last):
  File "/home/biommcwj/virtualenv/rrb_mnc/3.6/lib/python3.6/site-packages/django/db/backends/utils.py", line 84, in _execute
    return self.cursor.execute(sql, params)
  File "/home/biommcwj/virtualenv/rrb_mnc/3.6/lib/python3.6/site-packages/django/db/backends/mysql/base.py", line 73, in execute
    return self.cursor.execute(query, args)
  File "/home/biommcwj/virtualenv/rrb_mnc/3.6/lib64/python3.6/site-packages/MySQLdb/cursors.py", line 206, in execute
    res = self._query(query)
  File "/home/biommcwj/virtualenv/rrb_mnc/3.6/lib64/python3.6/site-packages/MySQLdb/cursors.py", line 319, in _query
    db.query(q)
  File "/home/biommcwj/virtualenv/rrb_mnc/3.6/lib64/python3.6/site-packages/MySQLdb/connections.py", line 254, in query
    _mysql.connection.query(self, query)
MySQLdb._exceptions.IntegrityError: (1062, "Duplicate entry 'dhalai' for key 'slug'")

The above exception was the direct cause of the following exception:

Traceback (most recent call last):
  File "/home/biommcwj/virtualenv/rrb_mnc/3.6/lib/python3.6/site-packages/django/core/handlers/exception.py", line 47, in inner
    response = get_response(request)
  File "/home/biommcwj/virtualenv/rrb_mnc/3.6/lib/python3.6/site-packages/django/core/handlers/base.py", line 181, in _get_response
    response = wrapped_callback(request, *callback_args, **callback_kwargs)
  File "/home/biommcwj/virtualenv/rrb_mnc/3.6/lib/python3.6/site-packages/django/contrib/admin/options.py", line 616, in wrapper
    return self.admin_site.admin_view(view)(*args, **kwargs)
  File "/home/biommcwj/virtualenv/rrb_mnc/3.6/lib/python3.6/site-packages/django/utils/decorators.py", line 130, in _wrapped_view
    response = view_func(request, *args, **kwargs)
  File "/home/biommcwj/virtualenv/rrb_mnc/3.6/lib/python3.6/site-packages/django/views/decorators/cache.py", line 44, in _wrapped_view_func
    response = view_func(request, *args, **kwargs)
  File "/home/biommcwj/virtualenv/rrb_mnc/3.6/lib/python3.6/site-packages/django/contrib/admin/sites.py", line 232, in inner
    return view(request, *args, **kwargs)
  File "/home/biommcwj/virtualenv/rrb_mnc/3.6/lib/python3.6/site-packages/django/contrib/admin/options.py", line 1657, in add_view
    return self.changeform_view(request, None, form_url, extra_context)
  File "/home/biommcwj/virtualenv/rrb_mnc/3.6/lib/python3.6/site-packages/django/utils/decorators.py", line 43, in _wrapper
    return bound_method(*args, **kwargs)
  File "/home/biommcwj/virtualenv/rrb_mnc/3.6/lib/python3.6/site-packages/django/utils/decorators.py", line 130, in _wrapped_view
    response = view_func(request, *args, **kwargs)
  File "/home/biommcwj/virtualenv/rrb_mnc/3.6/lib/python3.6/site-packages/django/contrib/admin/options.py", line 1540, in changeform_view
    return self._changeform_view(request, object_id, form_url, extra_context)
  File "/home/biommcwj/virtualenv/rrb_mnc/3.6/lib/python3.6/site-packages/django/contrib/admin/options.py", line 1586, in _changeform_view
    self.save_model(request, new_object, form, not add)
  File "/home/biommcwj/virtualenv/rrb_mnc/3.6/lib/python3.6/site-packages/django/contrib/admin/options.py", line 1099, in save_model
    obj.save()
  File "/home/biommcwj/rrb_mnc/main/models.py", line 79, in save
    super(Image, self).save(*args, **kwargs)
  File "/home/biommcwj/virtualenv/rrb_mnc/3.6/lib/python3.6/site-packages/django/db/models/base.py", line 727, in save
    force_update=force_update, update_fields=update_fields)
  File "/home/biommcwj/virtualenv/rrb_mnc/3.6/lib/python3.6/site-packages/django/db/models/base.py", line 765, in save_base
    force_update, using, update_fields,
  File "/home/biommcwj/virtualenv/rrb_mnc/3.6/lib/python3.6/site-packages/django/db/models/base.py", line 868, in _save_table
    results = self._do_insert(cls._base_manager, using, fields, returning_fields, raw)
  File "/home/biommcwj/virtualenv/rrb_mnc/3.6/lib/python3.6/site-packages/django/db/models/base.py", line 908, in _do_insert
    using=using, raw=raw,
  File "/home/biommcwj/virtualenv/rrb_mnc/3.6/lib/python3.6/site-packages/django/db/models/manager.py", line 85, in manager_method
    return getattr(self.get_queryset(), name)(*args, **kwargs)
  File "/home/biommcwj/virtualenv/rrb_mnc/3.6/lib/python3.6/site-packages/django/db/models/query.py", line 1270, in _insert
    return query.get_compiler(using=using).execute_sql(returning_fields)
  File "/home/biommcwj/virtualenv/rrb_mnc/3.6/lib/python3.6/site-packages/django/db/models/sql/compiler.py", line 1416, in execute_sql
    cursor.execute(sql, params)
  File "/home/biommcwj/virtualenv/rrb_mnc/3.6/lib/python3.6/site-packages/django/db/backends/utils.py", line 98, in execute
    return super().execute(sql, params)
  File "/home/biommcwj/virtualenv/rrb_mnc/3.6/lib/python3.6/site-packages/django/db/backends/utils.py", line 66, in execute
    return self._execute_with_wrappers(sql, params, many=False, executor=self._execute)
  File "/home/biommcwj/virtualenv/rrb_mnc/3.6/lib/python3.6/site-packages/django/db/backends/utils.py", line 75, in _execute_with_wrappers
    return executor(sql, params, many, context)
  File "/home/biommcwj/virtualenv/rrb_mnc/3.6/lib/python3.6/site-packages/django/db/backends/utils.py", line 84, in _execute
    return self.cursor.execute(sql, params)
  File "/home/biommcwj/virtualenv/rrb_mnc/3.6/lib/python3.6/site-packages/django/db/utils.py", line 90, in __exit__
    raise dj_exc_value.with_traceback(traceback) from exc_value
  File "/home/biommcwj/virtualenv/rrb_mnc/3.6/lib/python3.6/site-packages/django/db/backends/utils.py", line 84, in _execute
    return self.cursor.execute(sql, params)
  File "/home/biommcwj/virtualenv/rrb_mnc/3.6/lib/python3.6/site-packages/django/db/backends/mysql/base.py", line 73, in execute
    return self.cursor.execute(query, args)
  File "/home/biommcwj/virtualenv/rrb_mnc/3.6/lib64/python3.6/site-packages/MySQLdb/cursors.py", line 206, in execute
    res = self._query(query)
  File "/home/biommcwj/virtualenv/rrb_mnc/3.6/lib64/python3.6/site-packages/MySQLdb/cursors.py", line 319, in _query
    db.query(q)
  File "/home/biommcwj/virtualenv/rrb_mnc/3.6/lib64/python3.6/site-packages/MySQLdb/connections.py", line 254, in query
    _mysql.connection.query(self, query)
django.db.utils.IntegrityError: (1062, "Duplicate entry 'dhalai' for key 'slug'")
Not Found: /favicon.ico
Not Found: /uploads/default_land.jpg
Not Found: /uploads/default_land.jpg
Not Found: /favicon.ico
Not Found: /uploads/default_land.jpg
Not Found: /favicon.ico
Not Found: /uploads/default_land.jpg
Not Found: /favicon.ico
Not Found: /uploads/default_land.jpg
Not Found: /uploads/default_land.jpg
Not Found: /uploads/default_land.jpg
Not Found: /uploads/default_land.jpg
Not Found: /uploads/default_tall.jpg
Not Found: /uploads/default_square.jpg
Not Found: /favicon.ico
Not Found: /favicon.ico
Not Found: /uploads/default_land.jpg
Not Found: /favicon.ico
Not Found: /favicon.ico
Not Found: /favicon.ico
Not Found: /uploads/default_land.jpg
Not Found: /favicon.ico
Not Found: /favicon.ico
Not Found: /uploads/default_land.jpg
Not Found: /favicon.ico
Not Found: /favicon.ico
Not Found: /favicon.ico
Not Found: /favicon.ico
Not Found: /favicon.ico
Not Found: /favicon.ico
Internal Server Error: /admin/r/8/4/
Traceback (most recent call last):
  File "/home/biommcwj/virtualenv/rrb_mnc/3.6/lib/python3.6/site-packages/django/core/handlers/exception.py", line 47, in inner
    response = get_response(request)
  File "/home/biommcwj/virtualenv/rrb_mnc/3.6/lib/python3.6/site-packages/django/core/handlers/base.py", line 181, in _get_response
    response = wrapped_callback(request, *callback_args, **callback_kwargs)
  File "/home/biommcwj/virtualenv/rrb_mnc/3.6/lib/python3.6/site-packages/django/contrib/admin/sites.py", line 250, in wrapper
    return self.admin_view(view, cacheable)(*args, **kwargs)
  File "/home/biommcwj/virtualenv/rrb_mnc/3.6/lib/python3.6/site-packages/django/utils/decorators.py", line 130, in _wrapped_view
    response = view_func(request, *args, **kwargs)
  File "/home/biommcwj/virtualenv/rrb_mnc/3.6/lib/python3.6/site-packages/django/views/decorators/cache.py", line 44, in _wrapped_view_func
    response = view_func(request, *args, **kwargs)
  File "/home/biommcwj/virtualenv/rrb_mnc/3.6/lib/python3.6/site-packages/django/contrib/admin/sites.py", line 232, in inner
    return view(request, *args, **kwargs)
  File "/home/biommcwj/virtualenv/rrb_mnc/3.6/lib/python3.6/site-packages/django/contrib/contenttypes/views.py", line 35, in shortcut
    absurl = get_absolute_url()
  File "/home/biommcwj/rrb_mnc/main/models.py", line 67, in get_absolute_url
    return reverse('image-detail', kwargs={'slug': self.slug})
  File "/home/biommcwj/virtualenv/rrb_mnc/3.6/lib/python3.6/site-packages/django/urls/base.py", line 86, in reverse
    return resolver._reverse_with_prefix(view, prefix, *args, **kwargs)
  File "/home/biommcwj/virtualenv/rrb_mnc/3.6/lib/python3.6/site-packages/django/urls/resolvers.py", line 694, in _reverse_with_prefix
    raise NoReverseMatch(msg)
django.urls.exceptions.NoReverseMatch: Reverse for 'image-detail' with keyword arguments '{'slug': 'dhalai-xdfff'}' not found. 1 pattern(s) tried: ['category\\/(?P<slug1>[-a-zA-Z0-9_]+)\\/(?P<slug2>[-a-zA-Z0-9_]+)$']
Internal Server Error: /admin/r/8/4/
Traceback (most recent call last):
  File "/home/biommcwj/virtualenv/rrb_mnc/3.6/lib/python3.6/site-packages/django/core/handlers/exception.py", line 47, in inner
    response = get_response(request)
  File "/home/biommcwj/virtualenv/rrb_mnc/3.6/lib/python3.6/site-packages/django/core/handlers/base.py", line 181, in _get_response
    response = wrapped_callback(request, *callback_args, **callback_kwargs)
  File "/home/biommcwj/virtualenv/rrb_mnc/3.6/lib/python3.6/site-packages/django/contrib/admin/sites.py", line 250, in wrapper
    return self.admin_view(view, cacheable)(*args, **kwargs)
  File "/home/biommcwj/virtualenv/rrb_mnc/3.6/lib/python3.6/site-packages/django/utils/decorators.py", line 130, in _wrapped_view
    response = view_func(request, *args, **kwargs)
  File "/home/biommcwj/virtualenv/rrb_mnc/3.6/lib/python3.6/site-packages/django/views/decorators/cache.py", line 44, in _wrapped_view_func
    response = view_func(request, *args, **kwargs)
  File "/home/biommcwj/virtualenv/rrb_mnc/3.6/lib/python3.6/site-packages/django/contrib/admin/sites.py", line 232, in inner
    return view(request, *args, **kwargs)
  File "/home/biommcwj/virtualenv/rrb_mnc/3.6/lib/python3.6/site-packages/django/contrib/contenttypes/views.py", line 35, in shortcut
    absurl = get_absolute_url()
  File "/home/biommcwj/rrb_mnc/main/models.py", line 67, in get_absolute_url
    return reverse('image-detail', kwargs={'slug': self.slug})
  File "/home/biommcwj/virtualenv/rrb_mnc/3.6/lib/python3.6/site-packages/django/urls/base.py", line 86, in reverse
    return resolver._reverse_with_prefix(view, prefix, *args, **kwargs)
  File "/home/biommcwj/virtualenv/rrb_mnc/3.6/lib/python3.6/site-packages/django/urls/resolvers.py", line 694, in _reverse_with_prefix
    raise NoReverseMatch(msg)
django.urls.exceptions.NoReverseMatch: Reverse for 'image-detail' with keyword arguments '{'slug': 'dhalai-xdfff'}' not found. 1 pattern(s) tried: ['category\\/(?P<slug1>[-a-zA-Z0-9_]+)\\/(?P<slug2>[-a-zA-Z0-9_]+)$']
Forbidden (CSRF token missing or incorrect.): /admin/login/
Not Found: /favicon.ico
Not Found: /favicon.ico
Not Found: /favicon.ico
